Workbook

Sheet ORC DOM_2025
A1: ORÇAMENTO DOMÉSTICO
A5: MESES DO ANO | B5: % | C5: 46023 | D5: % | E5: 46054 | F5: % | G5: 46082 | H5: % | I5: 45748 | J5: % | K5: 45778 | L5: % | M5: 45809 | N5: % | O5: 45839 | P5: % | Q5: 45870 | R5: % | S5: 45901 | T5: % | U5: 45931 | V5: % | W5: 45962 | X5: % | Y5: 45992 | Z5: TOTAL ANO
A6: Receitas Fixas | C6: ATUAL | E6: SO FIXO | G6: 60% TOTAL | I6: 50% TT + COMPRAS CASA
A7: Fonte de Renda 1 (Líquido) - dia 1 | B7: =IFERROR(C7/C$20,0) -> 0.61823818 | C7: =1250+200+250-(1700*18.2%)-150 -> 1240.6 | D7: =IFERROR(E7/E$20,0) -> 0.40203932 | E7: =1250+200+250-(1700*18.2%)-300 -> 1090.6 | F7: =IFERROR(G7/G$20,0) -> 0.39467732 | G7: =1250+200+250-(1700*18.2%)-300 -> 1090.6 | H7: =IFERROR(I7/I$20,0) -> 0.41790724 | I7: =1250+200+250-(1700*18.2%)-300 -> 1090.6 | J7: =IFERROR(K7/K$20,0) -> 0 | L7: =IFERROR(M7/M$20,0) -> 0 | N7: =IFERROR(O7/O$20,0) -> 0 | P7: =IFERROR(Q7/Q$20,0) -> 0 | R7: =IFERROR(S7/S$20,0) -> 0 | T7: =IFERROR(U7/U$20,0) -> 0 | V7: =IFERROR(W7/W$20,0) -> 0 | X7: =IFERROR(Y7/Y$20,0) -> 0 | Z7: =C7+E7+G7+I7+K7+M7+O7+Q7+S7+U7+W7+Y7 -> 4512.4
A8: Pensão meninas | B8: =IFERROR(C8/C$20,0) -> 0.094684228 | C8: 190 | D8: =IFERROR(E8/E$20,0) -> 0.070041693 | E8: 190 | F8: =IFERROR(G8/G$20,0) -> 0.068759115 | G8: 190 | H8: =IFERROR(I8/I$20,0) -> 0.07280614 | I8: 190 | J8: =IFERROR(K8/K$20,0) -> 0 | L8: =IFERROR(M8/M$20,0) -> 0 | N8: =IFERROR(O8/O$20,0) -> 0 | P8: =IFERROR(Q8/Q$20,0) -> 0 | R8: =IFERROR(S8/S$20,0) -> 0 | T8: =IFERROR(U8/U$20,0) -> 0 | V8: =IFERROR(W8/W$20,0) -> 0 | X8: =IFERROR(Y8/Y$20,0) -> 0 | Z8: =C8+E8+G8+I8+K8+M8+O8+Q8+S8+U8+W8+Y8 -> 760
A9: Outros (Seg Social) - dia 16 | B9: =IFERROR(C9/C$20,0) -> 0.19139669 | C9: =(384.07) -> 384.07 | D9: =IFERROR(E9/E$20,0) -> 0.14158375 | E9: =(384.07) -> 384.07 | F9: =IFERROR(G9/G$20,0) -> 0.13899112 | G9: =(384.07) -> 384.07 | H9: =IFERROR(I9/I$20,0) -> 0.14717186 | I9: =(384.07) -> 384.07 | J9: =IFERROR(K9/K$20,0) -> 0 | L9: =IFERROR(M9/M$20,0) -> 0 | N9: =IFERROR(O9/O$20,0) -> 0 | P9: =IFERROR(Q9/Q$20,0) -> 0 | R9: =IFERROR(S9/S$20,0) -> 0 | T9: =IFERROR(U9/U$20,0) -> 0 | V9: =IFERROR(W9/W$20,0) -> 0 | X9: =IFERROR(Y9/Y$20,0) -> 0 | Z9: =C9+E9+G9+I9+K9+M9+O9+Q9+S9+U9+W9+Y9 -> 1536.28
A10: Vale refeição Norma | B10: =IFERROR(C10/C$20,0) -> 0.095680904 | C10: =9.6*20 -> 192 | D10: =IFERROR(E10/E$20,0) -> 0.070778974 | E10: =9.6*20 -> 192 | F10: =IFERROR(G10/G$20,0) -> 0.069482895 | G10: =9.6*20 -> 192 | H10: =IFERROR(I10/I$20,0) -> 0.073572521 | I10: =9.6*20 -> 192 | J10: =IFERROR(K10/K$20,0) -> 0
A11: Vale refeição Fernando | B11: =IFERROR(C11/C$20,0) -> 0 | D11: =IFERROR(E11/E$20,0) -> 0.070778974 | E11: =9.6*20 -> 192 | F11: =IFERROR(G11/G$20,0) -> 0.073825576 | G11: =10.2*20 -> 204 | H11: =IFERROR(I11/I$20,0) -> 0.078170803 | I11: =G11 -> 204 | J11: =IFERROR(K11/K$20,0) -> 0
A12: Apoio Fernando | B12: =IFERROR(C12/C$20,0) -> 0 | D12: =IFERROR(E12/E$20,0) -> 0.24477729 | E12: =SUM(E32:E40)-E11 -> 664 | F12: =IFERROR(G12/G$20,0) -> 0.25426397 | G12: =G31*60%-G11 -> 702.6 | H12: =IFERROR(I12/I$20,0) -> 0.21037143 | I12: =(I31*50%)-I11 -> 549 | J12: =IFERROR(K12/K$20,0) -> 0 | L12: =IFERROR(M12/M$20,0) -> 0 | N12: =IFERROR(O12/O$20,0) -> 0 | P12: =IFERROR(Q12/Q$20,0) -> 0 | R12: =IFERROR(S12/S$20,0) -> 0 | T12: =IFERROR(U12/U$20,0) -> 0 | V12: =IFERROR(W12/W$20,0) -> 0 | X12: =IFERROR(Y12/Y$20,0) -> 0 | Z12: =C12+E12+G12+I12+K12+M12+O12+Q12+S12+U12+W12+Y12 -> 1915.6
A13: Total Receitas Fixas | B13: =IFERROR(C13/C$20,0) -> 1 | C13: =SUM(C7:C12) -> 2006.67 | D13: =IFERROR(E13/E$20,0) -> 1 | E13: =SUM(E7:E12) -> 2712.67 | F13: =IFERROR(G13/G$20,0) -> 1 | G13: =SUM(G7:G12) -> 2763.27 | H13: =IFERROR(I13/I$20,0) -> 1 | I13: =SUM(I7:I12) -> 2609.67 | J13: =IFERROR(K13/K$20,0) -> 0 | K13: =SUM(K7:K12) -> 0 | L13: =IFERROR(M13/M$20,0) -> 0 | M13: =SUM(M7:M12) -> 0 | N13: =IFERROR(O13/O$20,0) -> 0 | O13: =SUM(O7:O12) -> 0 | P13: =IFERROR(Q13/Q$20,0) -> 0 | Q13: =SUM(Q7:Q12) -> 0 | R13: =IFERROR(S13/S$20,0) -> 0 | S13: =SUM(S7:S12) -> 0 | T13: =IFERROR(U13/U$20,0) -> 0 | U13: =SUM(U7:U12) -> 0 | V13: =IFERROR(W13/W$20,0) -> 0 | W13: =SUM(W7:W12) -> 0 | X13: =IFERROR(Y13/Y$20,0) -> 0 | Y13: =SUM(Y7:Y12) -> 0 | Z13: =C13+E13+G13+I13+K13+M13+O13+Q13+S13+U13+W13+Y13 -> 10092.28
A14: Receitas Variáveis Não Tributadas
A15: 13o. Salário Líquido | B15: =IFERROR(C15/C$20,0) -> 0 | D15: =IFERROR(E15/E$20,0) -> 0 | F15: =IFERROR(G15/G$20,0) -> 0 | H15: =IFERROR(I15/I$20,0) -> 0 | J15: =IFERROR(K15/K$20,0) -> 0 | L15: =IFERROR(M15/M$20,0) -> 0 | N15: =IFERROR(O15/O$20,0) -> 0 | P15: =IFERROR(Q15/Q$20,0) -> 0 | R15: =IFERROR(S15/S$20,0) -> 0 | T15: =IFERROR(U15/U$20,0) -> 0 | V15: =IFERROR(W15/W$20,0) -> 0 | X15: =IFERROR(Y15/Y$20,0) -> 0 | Z15: =C15+E15+G15+I15+K15+M15+O15+Q15+S15+U15+W15+Y15 -> 0
A16: Férias | B16: =IFERROR(C16/C$20,0) -> 0 | D16: =IFERROR(E16/E$20,0) -> 0 | F16: =IFERROR(G16/G$20,0) -> 0 | H16: =IFERROR(I16/I$20,0) -> 0 | J16: =IFERROR(K16/K$20,0) -> 0 | L16: =IFERROR(M16/M$20,0) -> 0 | N16: =IFERROR(O16/O$20,0) -> 0 | P16: =IFERROR(Q16/Q$20,0) -> 1 | Q16: 1000 | R16: =IFERROR(S16/S$20,0) -> 0 | T16: =IFERROR(U16/U$20,0) -> 0 | V16: =IFERROR(W16/W$20,0) -> 1 | W16: 1000 | X16: =IFERROR(Y16/Y$20,0) -> 0 | Z16: =C16+E16+G16+I16+K16+M16+O16+Q16+S16+U16+W16+Y16 -> 2000
A17: Bônus e extras | B17: =IFERROR(C17/C$20,0) -> 0 | D17: =IFERROR(E17/E$20,0) -> 0 | F17: =IFERROR(G17/G$20,0) -> 0 | H17: =IFERROR(I17/I$20,0) -> 0 | J17: =IFERROR(K17/K$20,0) -> 0 | L17: =IFERROR(M17/M$20,0) -> 0 | N17: =IFERROR(O17/O$20,0) -> 0 | P17: =IFERROR(Q17/Q$20,0) -> 0 | R17: =IFERROR(S17/S$20,0) -> 0 | T17: =IFERROR(U17/U$20,0) -> 0 | V17: =IFERROR(W17/W$20,0) -> 0 | X17: =IFERROR(Y17/Y$20,0) -> 0 | Z17: =C17+E17+G17+I17+K17+M17+O17+Q17+S17+U17+W17+Y17 -> 0
A18: Total Receitas Variáveis | B18: =IFERROR(C18/C$20,0) -> 0 | C18: =SUM(C15:C17) -> 0 | D18: =IFERROR(E18/E$20,0) -> 0 | E18: =SUM(E15:E17) -> 0 | F18: =IFERROR(G18/G$20,0) -> 0 | G18: =SUM(G15:G17) -> 0 | H18: =IFERROR(I18/I$20,0) -> 0 | I18: =SUM(I15:I17) -> 0 | J18: =IFERROR(K18/K$20,0) -> 0 | K18: =SUM(K15:K17) -> 0 | L18: =IFERROR(M18/M$20,0) -> 0 | M18: =SUM(M15:M17) -> 0 | N18: =IFERROR(O18/O$20,0) -> 0 | O18: =SUM(O15:O17) -> 0 | P18: =IFERROR(Q18/Q$20,0) -> 1 | Q18: =SUM(Q15:Q17) -> 1000 | R18: =IFERROR(S18/S$20,0) -> 0 | S18: =SUM(S15:S17) -> 0 | T18: =IFERROR(U18/U$20,0) -> 0 | U18: =SUM(U15:U17) -> 0 | V18: =IFERROR(W18/W$20,0) -> 1 | W18: =SUM(W15:W17) -> 1000 | X18: =IFERROR(Y18/Y$20,0) -> 0 | Y18: =SUM(Y15:Y17) -> 0 | Z18: =SUM(Z15:Z17) -> 2000
A20: Renda Total | B20: 1 | C20: =C18+C13 -> 2006.67 | D20: 1 | E20: =E18+E13 -> 2712.67 | F20: 1 | G20: =G18+G13 -> 2763.27 | H20: 1 | I20: =I18+I13 -> 2609.67 | J20: 1 | K20: =K18+K13 -> 0 | L20: 1 | M20: =M18+M13 -> 0 | N20: 1 | O20: =O18+O13 -> 0 | P20: 1 | Q20: =Q18+Q13 -> 1000 | R20: 1 | S20: =S18+S13 -> 0 | T20: 1 | U20: =U18+U13 -> 0 | V20: 1 | W20: =W18+W13 -> 1000 | X20: 1 | Y20: =Y18+Y13 -> 0 | Z20: =Z18+Z13 -> 12092.28
A22: BOLETO PESSOAL | B22: =IFERROR(C22/C$20,0) -> 0 | C22: =SUM(C23:C28) -> 0 | D22: =IFERROR(E22/E$20,0) -> 0.092160123 | E22: =SUM(E23:E28) -> 250 | F22: =IFERROR(G22/G$20,0) -> 0.09047252 | G22: =SUM(G23:G28) -> 250 | H22: =IFERROR(I22/I$20,0) -> 0.095797553 | I22: =SUM(I23:I28) -> 250 | J22: =IFERROR(K22/K$20,0) -> 0 | K22: =SUM(K23:K28) -> 250 | L22: =IFERROR(M22/M$20,0) -> 0 | M22: =SUM(M23:M28) -> 250 | N22: =IFERROR(O22/O$20,0) -> 0 | O22: =SUM(O23:O28) -> 250 | P22: =IFERROR(Q22/Q$20,0) -> 1.25 | Q22: =SUM(Q23:Q28) -> 1250 | R22: =IFERROR(S22/S$20,0) -> 0 | S22: =SUM(S23:S28) -> 250 | T22: =IFERROR(U22/U$20,0) -> 0 | U22: =SUM(U23:U28) -> 250 | V22: =IFERROR(W22/W$20,0) -> 1.25 | W22: =SUM(W23:W28) -> 1250 | X22: =IFERROR(Y22/Y$20,0) -> 0 | Y22: =SUM(Y23:Y28) -> 250 | Z22: =C22+E22+G22+I22+K22+M22+O22+Q22+S22+U22+W22+Y22 -> 4750
A23: META - 1 ano ( pagar divida bitcoin) | B23: =IFERROR(C23/C$20,0) -> 0 | D23: =IFERROR(E23/E$20,0) -> 0 | F23: =IFERROR(G23/G$20,0) -> 0 | H23: =IFERROR(I23/I$20,0) -> 0 | J23: =IFERROR(K23/K$20,0) -> 0 | L23: =IFERROR(M23/M$20,0) -> 0 | N23: =IFERROR(O23/O$20,0) -> 0 | P23: =IFERROR(Q23/Q$20,0) -> 0 | R23: =IFERROR(S23/S$20,0) -> 0 | T23: =IFERROR(U23/U$20,0) -> 0 | V23: =IFERROR(W23/W$20,0) -> 0 | W23: =U23 | X23: =IFERROR(Y23/Y$20,0) -> 0 | Z23: =C23+E23+G23+I23+K23+M23+O23+Q23+S23+U23+W23+Y23 -> 0
A24: META - 1 ano (quitação do carro) | B24: =IFERROR(C24/C$20,0) -> 0 | D24: =IFERROR(E24/E$20,0) -> 0 | F24: =IFERROR(G24/G$20,0) -> 0 | H24: =IFERROR(I24/I$20,0) -> 0 | J24: =IFERROR(K24/K$20,0) -> 0 | L24: =IFERROR(M24/M$20,0) -> 0 | N24: =IFERROR(O24/O$20,0) -> 0 | P24: =IFERROR(Q24/Q$20,0) -> 0 | R24: =IFERROR(S24/S$20,0) -> 0 | T24: =IFERROR(U24/U$20,0) -> 0 | V24: =IFERROR(W24/W$20,0) -> 0 | W24: =U24 | X24: =IFERROR(Y24/Y$20,0) -> 0 | Z24: =C24+E24+G24+I24+K24+M24+O24+Q24+S24+U24+W24+Y24 -> 0
A25: META - 1 ano (Viagem Brasil) | B25: =IFERROR(C25/C$20,0) -> 0 | D25: =IFERROR(E25/E$20,0) -> 0.092160123 | E25: 250 | F25: =IFERROR(I25/G$20,0) -> 0.09047252 | G25: 250 | H25: =IFERROR(#REF!/I$20,0) -> 0 | I25: 250 | J25: =IFERROR(K25/K$20,0) -> 0 | K25: 250 | L25: =IFERROR(M25/M$20,0) -> 0 | M25: 250 | N25: =IFERROR(O25/O$20,0) -> 0 | O25: 250 | P25: =IFERROR(Q25/Q$20,0) -> 1.25 | Q25: 1250 | R25: =IFERROR(S25/S$20,0) -> 0 | S25: 250 | T25: =IFERROR(U25/U$20,0) -> 0 | U25: 250 | V25: =IFERROR(W25/W$20,0) -> 1.25 | W25: 1250 | X25: =IFERROR(Y25/Y$20,0) -> 0 | Y25: 250 | Z25: =C25+E25+G25+I25+K25+M25+O25+Q25+S25+U25+W25+Y25 -> 4750
A26: META - 8 meses ( Férias Verão) | B26: =IFERROR(C26/C$20,0) -> 0 | D26: =IFERROR(E26/E$20,0) -> 0 | F26: =IFERROR(I26/G$20,0) -> 0 | H26: =IFERROR(#REF!/I$20,0) -> 0 | J26: =IFERROR(K26/K$20,0) -> 0 | L26: =IFERROR(M26/M$20,0) -> 0 | N26: =IFERROR(O26/O$20,0) -> 0 | P26: =IFERROR(Q26/Q$20,0) -> 0 | R26: =IFERROR(S26/S$20,0) -> 0 | T26: =IFERROR(U26/U$20,0) -> 0 | V26: =IFERROR(W26/W$20,0) -> 0 | X26: =IFERROR(Y26/Y$20,0) -> 0 | Z26: =C26+E26+G26+I26+K26+M26+O26+Q26+S26+U26+W26+Y26 -> 0
A27: METONA ( Casa Própria - 10 anos ) | B27: =IFERROR(C27/C$20,0) -> 0 | D27: =IFERROR(E27/E$20,0) -> 0 | F27: =IFERROR(G27/G$20,0) -> 0 | H27: =IFERROR(I27/I$20,0) -> 0 | J27: =IFERROR(K27/K$20,0) -> 0 | L27: =IFERROR(M27/M$20,0) -> 0 | N27: =IFERROR(O27/O$20,0) -> 0 | P27: =IFERROR(Q27/Q$20,0) -> 0 | R27: =IFERROR(S27/S$20,0) -> 0 | T27: =IFERROR(U27/U$20,0) -> 0 | V27: =IFERROR(W27/W$20,0) -> 0 | X27: =IFERROR(Y27/Y$20,0) -> 0 | Z27: =C27+E27+G27+I27+K27+M27+O27+Q27+S27+U27+W27+Y27 -> 0
A28: METAZONA ( Aposentadoria - 30 anos ) | B28: =IFERROR(C28/C$20,0) -> 0 | D28: =IFERROR(E28/E$20,0) -> 0 | F28: =IFERROR(G28/G$20,0) -> 0 | H28: =IFERROR(I28/I$20,0) -> 0 | J28: =IFERROR(K28/K$20,0) -> 0 | L28: =IFERROR(M28/M$20,0) -> 0 | N28: =IFERROR(O28/O$20,0) -> 0 | P28: =IFERROR(Q28/Q$20,0) -> 0 | R28: =IFERROR(S28/S$20,0) -> 0 | T28: =IFERROR(U28/U$20,0) -> 0 | V28: =IFERROR(W28/W$20,0) -> 0 | X28: =IFERROR(Y28/Y$20,0) -> 0 | Z28: =C28+E28+G28+I28+K28+M28+O28+Q28+S28+U28+W28+Y28 -> 0
A29: TOTAL BOLETO PESSOAL (30%) | B29: =IFERROR(C29/C$20,0) -> 0 | C29: =C22 -> 0 | D29: =IFERROR(E29/E$20,0) -> 0.092160123 | E29: =E22 -> 250 | F29: =IFERROR(G29/G$20,0) -> 0.09047252 | G29: =G22 -> 250 | H29: =IFERROR(I29/I$20,0) -> 0.095797553 | I29: =I22 -> 250 | J29: =IFERROR(K29/K$20,0) -> 0 | K29: =K22 -> 250 | L29: =IFERROR(M29/M$20,0) -> 0 | M29: =M22 -> 250 | N29: =IFERROR(O29/O$20,0) -> 0 | O29: =O22 -> 250 | P29: =IFERROR(Q29/Q$20,0) -> 1.25 | Q29: =Q22 -> 1250 | R29: =IFERROR(S29/S$20,0) -> 0 | S29: =S22 -> 250 | T29: =IFERROR(U29/U$20,0) -> 0 | U29: =U22 -> 250 | V29: =IFERROR(W29/W$20,0) -> 1.25 | W29: =W22 -> 1250 | X29: =IFERROR(Y29/Y$20,0) -> 0 | Y29: =Y22 -> 250 | Z29: =SUM(Z23:Z28) -> 4750
A31: HABITAÇÃO | B31: =IFERROR(C31/C$20,0) -> 0.67350386 | C31: =SUM(C32:C45) -> 1351.5 | D31: =IFERROR(E31/E$20,0) -> 0.55701578 | E31: =SUM(E32:E45) -> 1511 | F31: =IFERROR(G31/G$20,0) -> 0.54681591 | G31: =SUM(G32:G45) -> 1511 | H31: =IFERROR(I31/I$20,0) -> 0.57708446 | I31: =SUM(I32:I45) -> 1506 | J31: =IFERROR(K31/K$20,0) -> 0 | K31: =SUM(K32:K45) -> 1506 | L31: =IFERROR(M31/M$20,0) -> 0 | M31: =SUM(M32:M45) -> 1506 | N31: =IFERROR(O31/O$20,0) -> 0 | O31: =SUM(O32:O45) -> 1506 | P31: =IFERROR(Q31/Q$20,0) -> 1.506 | Q31: =SUM(Q32:Q45) -> 1506 | R31: =IFERROR(S31/S$20,0) -> 0 | S31: =SUM(S32:S45) -> 1506 | T31: =IFERROR(U31/U$20,0) -> 0 | U31: =SUM(U32:U45) -> 1506 | V31: =IFERROR(W31/W$20,0) -> 1.506 | W31: =SUM(W32:W45) -> 1506 | X31: =IFERROR(Y31/Y$20,0) -> 0 | Y31: =SUM(Y32:Y45) -> 1506 | Z31: =C31+E31+G31+I31+K31+M31+O31+Q31+S31+U31+W31+Y31 -> 17927.5
A32: Aluguel | B32: =IFERROR(C32/C$20,0) -> 0.34883663 | C32: 700 | D32: =IFERROR(E32/E$20,0) -> 0.25804834 | E32: 700 | F32: =IFERROR(G32/G$20,0) -> 0.25332306 | G32: 700 | H32: =IFERROR(I32/I$20,0) -> 0.26823315 | I32: 700 | J32: =IFERROR(K32/K$20,0) -> 0 | K32: 700 | L32: =IFERROR(M32/M$20,0) -> 0 | M32: 700 | N32: =IFERROR(O32/O$20,0) -> 0 | O32: 700 | P32: =IFERROR(Q32/Q$20,0) -> 0.7 | Q32: 700 | R32: =IFERROR(S32/S$20,0) -> 0 | S32: 700 | T32: =IFERROR(U32/U$20,0) -> 0 | U32: 700 | V32: =IFERROR(W32/W$20,0) -> 0.7 | W32: 700 | X32: =IFERROR(Y32/Y$20,0) -> 0 | Y32: 700 | Z32: =C32+E32+G32+I32+K32+M32+O32+Q32+S32+U32+W32+Y32 -> 8400
A33: Condomínio | B33: =IFERROR(C33/C$20,0) -> 0 | D33: =IFERROR(E33/E$20,0) -> 0 | F33: =IFERROR(G33/G$20,0) -> 0 | H33: =IFERROR(I33/I$20,0) -> 0 | J33: =IFERROR(K33/K$20,0) -> 0 | L33: =IFERROR(M33/M$20,0) -> 0 | N33: =IFERROR(O33/O$20,0) -> 0 | P33: =IFERROR(Q33/Q$20,0) -> 0 | R33: =IFERROR(S33/S$20,0) -> 0 | T33: =IFERROR(U33/U$20,0) -> 0 | V33: =IFERROR(W33/W$20,0) -> 0 | X33: =IFERROR(Y33/Y$20,0) -> 0 | Z33: =C33+E33+G33+I33+K33+M33+O33+Q33+S33+U33+W33+Y33 -> 0
A34: IPTU | B34: =IFERROR(C34/C$20,0) -> 0 | D34: =IFERROR(E34/E$20,0) -> 0 | F34: =IFERROR(G34/G$20,0) -> 0 | H34: =IFERROR(I34/I$20,0) -> 0 | J34: =IFERROR(K34/K$20,0) -> 0 | L34: =IFERROR(M34/M$20,0) -> 0 | N34: =IFERROR(O34/O$20,0) -> 0 | P34: =IFERROR(Q34/Q$20,0) -> 0 | R34: =IFERROR(S34/S$20,0) -> 0 | T34: =IFERROR(U34/U$20,0) -> 0 | V34: =IFERROR(W34/W$20,0) -> 0 | X34: =IFERROR(Y34/Y$20,0) -> 0 | Z34: =C34+E34+G34+I34+K34+M34+O34+Q34+S34+U34+W34+Y34 -> 0
A35: Conta de água | B35: =IFERROR(C35/C$20,0) -> 0.024916902 | C35: 50 | D35: =IFERROR(E35/E$20,0) -> 0.018432025 | E35: 50 | F35: =IFERROR(G35/G$20,0) -> 0.018094504 | G35: 50 | H35: =IFERROR(I35/I$20,0) -> 0.01724356 | I35: 45 | J35: =IFERROR(K35/K$20,0) -> 0 | K35: 45 | L35: =IFERROR(M35/M$20,0) -> 0 | M35: 45 | N35: =IFERROR(O35/O$20,0) -> 0 | O35: 45 | P35: =IFERROR(Q35/Q$20,0) -> 0.045 | Q35: 45 | R35: =IFERROR(S35/S$20,0) -> 0 | S35: 45 | T35: =IFERROR(U35/U$20,0) -> 0 | U35: 45 | V35: =IFERROR(W35/W$20,0) -> 0.045 | W35: 45 | X35: =IFERROR(Y35/Y$20,0) -> 0 | Y35: 45 | Z35: =C35+E35+G35+I35+K35+M35+O35+Q35+S35+U35+W35+Y35 -> 555
A36: Conta de energia - 09 | B36: =IFERROR(C36/C$20,0) -> 0.015458446 | C36: 31.02 | D36: =IFERROR(E36/E$20,0) -> 0.012902417 | E36: 35 | F36: =IFERROR(G36/G$20,0) -> 0.012666153 | G36: 35 | H36: =IFERROR(I36/I$20,0) -> 0.013411657 | I36: 35 | J36: =IFERROR(K36/K$20,0) -> 0 | K36: 35 | L36: =IFERROR(M36/M$20,0) -> 0 | M36: 35 | N36: =IFERROR(O36/O$20,0) -> 0 | O36: 35 | P36: =IFERROR(Q36/Q$20,0) -> 0.035 | Q36: 35 | R36: =IFERROR(S36/S$20,0) -> 0 | S36: 35 | T36: =IFERROR(U36/U$20,0) -> 0 | U36: 35 | V36: =IFERROR(W36/W$20,0) -> 0.035 | W36: 35 | X36: =IFERROR(Y36/Y$20,0) -> 0 | Y36: 35 | Z36: =C36+E36+G36+I36+K36+M36+O36+Q36+S36+U36+W36+Y36 -> 416.02
A37: Seguro Residencial | B37: =IFERROR(C37/C$20,0) -> 0 | D37: =IFERROR(E37/E$20,0) -> 0 | F37: =IFERROR(G37/G$20,0) -> 0 | H37: =IFERROR(I37/I$20,0) -> 0 | J37: =IFERROR(K37/K$20,0) -> 0 | L37: =IFERROR(M37/M$20,0) -> 0 | N37: =IFERROR(O37/O$20,0) -> 0 | P37: =IFERROR(Q37/Q$20,0) -> 0 | R37: =IFERROR(S37/S$20,0) -> 0 | T37: =IFERROR(U37/U$20,0) -> 0 | V37: =IFERROR(W37/W$20,0) -> 0 | X37: =IFERROR(Y37/Y$20,0) -> 0 | Z37: =C37+E37+G37+I37+K37+M37+O37+Q37+S37+U37+W37+Y37 -> 0
A38: Conta de gás | B38: =IFERROR(C38/C$20,0) -> 0.014691005 | C38: 29.48 | D38: =IFERROR(E38/E$20,0) -> 0.012902417 | E38: 35 | F38: =IFERROR(G38/G$20,0) -> 0.012666153 | G38: 35 | H38: =IFERROR(I38/I$20,0) -> 0.013411657 | I38: 35 | J38: =IFERROR(K38/K$20,0) -> 0 | K38: 35 | L38: =IFERROR(M38/M$20,0) -> 0 | M38: 35 | N38: =IFERROR(O38/O$20,0) -> 0 | O38: 35 | P38: =IFERROR(Q38/Q$20,0) -> 0.035 | Q38: 35 | R38: =IFERROR(S38/S$20,0) -> 0 | S38: 35 | T38: =IFERROR(U38/U$20,0) -> 0 | U38: 35 | V38: =IFERROR(W38/W$20,0) -> 0.035 | W38: 35 | X38: =IFERROR(Y38/Y$20,0) -> 0 | Y38: 35 | Z38: =C38+E38+G38+I38+K38+M38+O38+Q38+S38+U38+W38+Y38 -> 414.48
A39: Celular+TV+internet | B39: =IFERROR(C39/C$20,0) -> 0.01794017 | C39: 36 | D39: =IFERROR(E39/E$20,0) -> 0.013271058 | E39: 36 | F39: =IFERROR(G39/G$20,0) -> 0.013028043 | G39: 36 | H39: =IFERROR(I39/I$20,0) -> 0.013794848 | I39: 36 | J39: =IFERROR(K39/K$20,0) -> 0 | K39: 36 | L39: =IFERROR(M39/M$20,0) -> 0 | M39: 36 | N39: =IFERROR(O39/O$20,0) -> 0 | O39: 36 | P39: =IFERROR(Q39/Q$20,0) -> 0.036 | Q39: 36 | R39: =IFERROR(S39/S$20,0) -> 0 | S39: 36 | T39: =IFERROR(U39/U$20,0) -> 0 | U39: 36 | V39: =IFERROR(W39/W$20,0) -> 0.036 | W39: 36 | X39: =IFERROR(Y39/Y$20,0) -> 0 | Y39: 36 | Z39: =C39+E39+G39+I39+K39+M39+O39+Q39+S39+U39+W39+Y39 -> 432
A40: Celular | B40: =IFERROR(C40/C$20,0) -> 0 | D40: =IFERROR(E40/E$20,0) -> 0 | F40: =IFERROR(G40/G$20,0) -> 0 | H40: =IFERROR(I40/I$20,0) -> 0 | J40: =IFERROR(K40/K$20,0) -> 0 | L40: =IFERROR(M40/M$20,0) -> 0 | N40: =IFERROR(O40/O$20,0) -> 0 | P40: =IFERROR(Q40/Q$20,0) -> 0 | R40: =IFERROR(S40/S$20,0) -> 0 | T40: =IFERROR(U40/U$20,0) -> 0 | V40: =IFERROR(W40/W$20,0) -> 0 | X40: =IFERROR(Y40/Y$20,0) -> 0 | Z40: =C40+E40+G40+I40+K40+M40+O40+Q40+S40+U40+W40+Y40 -> 0
A41: Amazon Prime / Netflix | B41: =IFERROR(C41/C$20,0) -> 0.0024916902 | C41: 5 | D41: =IFERROR(E41/E$20,0) -> 0.0018432025 | E41: 5 | F41: =IFERROR(G41/G$20,0) -> 0.0018094504 | G41: 5 | H41: =IFERROR(I41/I$20,0) -> 0.0019159511 | I41: 5 | J41: =IFERROR(K41/K$20,0) -> 0 | K41: 5 | L41: =IFERROR(M41/M$20,0) -> 0 | M41: 5 | N41: =IFERROR(O41/O$20,0) -> 0 | O41: 5 | P41: =IFERROR(Q41/Q$20,0) -> 0.005 | Q41: 5 | R41: =IFERROR(S41/S$20,0) -> 0 | S41: 5 | T41: =IFERROR(U41/U$20,0) -> 0 | U41: 5 | V41: =IFERROR(W41/W$20,0) -> 0.005 | W41: 5 | X41: =IFERROR(Y41/Y$20,0) -> 0 | Y41: 5 | Z41: =C41+E41+G41+I41+K41+M41+O41+Q41+S41+U41+W41+Y41 -> 60
A42: Supermercado | B42: =IFERROR(C42/C$20,0) -> 0.19933522 | C42: 400 | D42: =IFERROR(E42/E$20,0) -> 0.1474562 | E42: 400 | F42: =IFERROR(G42/G$20,0) -> 0.14475603 | G42: 400 | H42: =IFERROR(I42/I$20,0) -> 0.15327608 | I42: 400 | J42: =IFERROR(K42/K$20,0) -> 0 | K42: 400 | L42: =IFERROR(M42/M$20,0) -> 0 | M42: 400 | N42: =IFERROR(O42/O$20,0) -> 0 | O42: 400 | P42: =IFERROR(Q42/Q$20,0) -> 0.4 | Q42: 400 | R42: =IFERROR(S42/S$20,0) -> 0 | S42: 400 | T42: =IFERROR(U42/U$20,0) -> 0 | U42: 400 | V42: =IFERROR(W42/W$20,0) -> 0.4 | W42: 400 | X42: =IFERROR(Y42/Y$20,0) -> 0 | Y42: 400 | Z42: =C42+E42+G42+I42+K42+M42+O42+Q42+S42+U42+W42+Y42 -> 4800
A43: Feira | B43: =IFERROR(C43/C$20,0) -> 0 | C43: 0 | D43: =IFERROR(E43/E$20,0) -> 0.018432025 | E43: 50 | F43: =IFERROR(G43/G$20,0) -> 0.018094504 | G43: 50 | H43: =IFERROR(I43/I$20,0) -> 0.019159511 | I43: 50 | J43: =IFERROR(K43/K$20,0) -> 0 | K43: 50 | L43: =IFERROR(M43/M$20,0) -> 0 | M43: 50 | N43: =IFERROR(O43/O$20,0) -> 0 | O43: 50 | P43: =IFERROR(Q43/Q$20,0) -> 0.05 | Q43: 50 | R43: =IFERROR(S43/S$20,0) -> 0 | S43: 50 | T43: =IFERROR(U43/U$20,0) -> 0 | U43: 50 | V43: =IFERROR(W43/W$20,0) -> 0.05 | W43: 50 | X43: =IFERROR(Y43/Y$20,0) -> 0 | Y43: 50 | Z43: =C43+E43+G43+I43+K43+M43+O43+Q43+S43+U43+W43+Y43 -> 550
A44: Açougue | B44: =IFERROR(C44/C$20,0) -> 0.049833804 | C44: 100 | D44: =IFERROR(E44/E$20,0) -> 0.073728098 | E44: 200 | F44: =IFERROR(G44/G$20,0) -> 0.072378016 | G44: 200 | H44: =IFERROR(I44/I$20,0) -> 0.076638042 | I44: 200 | J44: =IFERROR(K44/K$20,0) -> 0 | K44: 200 | L44: =IFERROR(M44/M$20,0) -> 0 | M44: 200 | N44: =IFERROR(O44/O$20,0) -> 0 | O44: 200 | P44: =IFERROR(Q44/Q$20,0) -> 0.2 | Q44: 200 | R44: =IFERROR(S44/S$20,0) -> 0 | S44: 200 | T44: =IFERROR(U44/U$20,0) -> 0 | U44: 200 | V44: =IFERROR(W44/W$20,0) -> 0.2 | W44: 200 | X44: =IFERROR(Y44/Y$20,0) -> 0 | Y44: 200 | Z44: =C44+E44+G44+I44+K44+M44+O44+Q44+S44+U44+W44+Y44 -> 2300
A45: Faxineira | B45: =IFERROR(C45/C$20,0) -> 0 | D45: =IFERROR(E45/E$20,0) -> 0 | F45: =IFERROR(G45/G$20,0) -> 0 | H45: =IFERROR(I45/I$20,0) -> 0 | J45: =IFERROR(K45/K$20,0) -> 0 | L45: =IFERROR(M45/M$20,0) -> 0 | N45: =IFERROR(O45/O$20,0) -> 0 | P45: =IFERROR(Q45/Q$20,0) -> 0 | R45: =IFERROR(S45/S$20,0) -> 0 | T45: =IFERROR(U45/U$20,0) -> 0 | V45: =IFERROR(W45/W$20,0) -> 0 | X45: =IFERROR(Y45/Y$20,0) -> 0 | Z45: =C45+E45+G45+I45+K45+M45+O45+Q45+S45+U45+W45+Y45 -> 0
A46: DIVÍDAS | B46: =IFERROR(C46/C$20,0) -> 0.082629431 | C46: =SUM(C47:C52) -> 165.81 | D46: =IFERROR(E46/E$20,0) -> 0.06112428 | E46: =SUM(E47:E52) -> 165.81 | F46: =IFERROR(G46/G$20,0) -> 0.060004994 | G46: =SUM(G47:G52) -> 165.81 | H46: =IFERROR(I46/I$20,0) -> 0.063536769 | I46: =SUM(I47:I52) -> 165.81 | J46: =IFERROR(K46/K$20,0) -> 0 | K46: =SUM(K47:K52) -> 165.81 | L46: =IFERROR(M46/M$20,0) -> 0 | M46: =SUM(M47:M52) -> 165.81 | N46: =IFERROR(O46/O$20,0) -> 0 | O46: =SUM(O47:O52) -> 165.81 | P46: =IFERROR(Q46/Q$20,0) -> 0.16072 | Q46: =SUM(Q47:Q52) -> 160.72 | R46: =IFERROR(S46/S$20,0) -> 0 | S46: =SUM(S47:S52) -> 104.81 | T46: =IFERROR(U46/U$20,0) -> 0 | U46: =SUM(U47:U52) -> 98.31 | V46: =IFERROR(W46/W$20,0) -> 0.09181 | W46: =SUM(W47:W52) -> 91.81 | X46: =IFERROR(Y46/Y$20,0) -> 0 | Y46: =SUM(Y47:Y52) -> 104.81 | Z46: =C46+E46+G46+I46+K46+M46+O46+Q46+S46+U46+W46+Y46 -> 1721.13
...

Sheet OBJ_2026
B1: SALARIO BASE | G1: OBJETIVO | H1: ESTRATEGIA | I1: VALOR | J1: ATE | N1: 2024 | O1: 2025 | P1: 2026
F2: 1 | G2: Ganhos liquidos acima 2500 euros/mes | H2: Empreender - Vinhos verdes | N2: ANO 1 | O2: ANO 2 | P2: ANO 3 | Q2: ANO 4 | R2: ANO 5 | S2: ANO 6 | T2: ANO 7 | U2: ANO 8 | V2: ANO 9 | W2: ANO 10 | Z2: TOTAL
B3: Salario | C3: anual | D3: mensal | H3: Buscar trabalho com maior ganho | J3: 45778 | L3: TOTAL DA DIVIDA | M3: 13080 | N3: 1308 | O3: 1308 | P3: 1308 | Q3: 1308 | R3: 1308 | S3: 1308 | T3: 1308 | U3: 1308 | V3: 1308 | W3: 1308
B4: base | C4: 14000 | D4: =C4/12 -> 1166.6667 | H4: Fazer trabalho extra | N4: 2616 | O4: 2616 | P4: 2616 | Q4: 2616 | R4: 2616
B5: comissões | C5: =D5*12 -> 456 | D5: 38 | L5: ATÉ JUL/27 | N5: 4360 | O5: 4360 | P5: 4360
B6: desempenho | C6: =D6*12 -> 192 | D6: 16 | F6: 2 | G6: Quitação carro Nissan Juke | H6: Aplicar bitcoin - 244 por 6 meses | I6: =244*6 -> 1464 | J6: julho | N6: =V18 -> 0.5652 | O6: =V20 -> 1
B7: horario | C7: =D7*12 -> 324 | D7: 27 | H7: Aplicar bitcoin - 244 por 6 meses+premio | I7: =(244*6)+800 -> 2264 | J7: dezembro
C8: =SUM(C4:C7) -> 14972 | D8: 1006
B9: Previdencia | C9: =D9*12 -> 1509 | D9: =D8*12.5% -> 125.75 | F9: 3 | G9: Presente mae ( Portugal) | H9: abril a julho | I9: =(2500+260)/6 -> 460 | J9: julho | N9: jan | O9: fev | P9: mar | Q9: abr | R9: mai | S9: jun | T9: jul | U9: ago | V9: set | W9: out | X9: nov | Y9: dez
B10: Total liquido | C10: =C8-C9 -> 13463 | D10: 880 | L10: total ano | M10: 4360 | N10: 363 | O10: 363 | P10: 363 | Q10: 363 | R10: 363 | S10: 363 | T10: 363 | U10: 363 | V10: 363 | W10: 363 | X10: 363 | Y10: 363 | Z10: =SUM(N10:Y10) -> 4356
B11: VR | D11: 192 | F11: 4 | G11: Férias com mae/filhas | H11: Férias Verão (Ago/Set ) | I11: =900 -> 900 | J11: agosto | L11: total mes | N11: 109 | O11: 109 | P11: 109 | Q11: 109 | R11: 109 | S11: 109 | T11: 109 | U11: 109 | V11: 109 | W11: 109 | X11: 109 | Y11: 109 | Z11: =SUM(N11:Y11) -> 1308
D12: 1072 | L12: total ferias/natal | M12: 4251 | N12: 254 | O12: 254 | P12: 254 | Q12: 254 | R12: 254 | S12: 254 | T12: 254 | U12: 254 | V12: 254 | W12: 254 | X12: 254 | Y12: 254 | Z12: =SUM(N12:Y12) -> 3048
F13: 5 | G13: VIAJAR COM MENINAS | H13: 13 salario | I13: =900 -> 900 | J13: dezembro | R13: a pagar | S13: =SUM(N10:S10) -> 2178
M14: 6540 | R14: sera pago mensal | S14: =SUM(N11:S11) -> 654
B15: PARCELA ACORDO CAN UP | M15: 60 | R15: Bitcoin | S15: =S13-S14 -> 1524
H16: VALOR | I16: VALOR BIT | J16: QTD BIT
B17: 1 parcela | C17: 1890 | D17: 45170 | G17: JANEIRO | L17: 48.65 | M17: ano 1 | N17: 6 meses | O17: 109 | P17: 3.3 | Q17: 29 | R17: dez./24 | S17: 1410.94 | T17: 86 | U17: 115 | V17: 0.2522
B18: 2 parcela | C18: 1890 | D18: 45200 | G18: FEVEREIRO | N18: 6 meses | O18: 109 | P18: 3.3 | Q18: 36 | R18: 45839 | S18: 1459.59 | T18: 50 | V18: 0.5652
B19: 3 parcela | C19: 1260 | D19: 45231 | G19: MARÇO | L19: 1
B20: 4 parcela | C20: 1260 | D20: 45261 | G20: ABRIL | M20: ano 2 | N20: 6 meses | O20: 109 | P20: 3.3 | Q20: 50 | R20: dez./25 | S20: 2140.74 | T20: - | V20: 1
B21: 5 parcela | C21: 1260 | D21: 45292 | G21: MAIO | N21: 6 meses | O21: 109 | P21: 3.3 | Q21: - | R21: mai./26 | S21: 0 | V21: 1
B22: 6 parcela | C22: 1260 | D22: 45323 | G22: JUNHO | J22: =I6+(I6*30%) -> 1903.2
B23: 7 parcela | C23: 1260 | D23: 45352
B24: 8 parcela | C24: 1260 | D24: 45383
B25: 9 parcela | C25: 1260 | D25: 45413 | G25: apoio Municipal / Federal para aluguel | I25: =400 -> 400 | J25: ate julho
B26: 10 parcela | C26: 1260 | D26: 45444
B27: 11 parcela | C27: 1260 | D27: 45474 | G27: O QUE IMPORTA | L27: 46357 | N27: visitar Brasil 3 seman as | P27: =700*3 -> 2100 | Q27: passagens | R27: =6*300 -> 1800 | S27: comprar em Jul/26
B28: 12 parcela | C28: 1260 | D28: 45505 | P28: =P27 -> 2100 | Q28: férias/festa/viagem
B29: 13 parcela | C29: 1260 | D29: 45536 | G29: tempo de qualidade com as meninas
B30: 14 parcela | C30: 1260 | D30: 45566 | G30: cuidar da minha mente e corpo | P30: 2000 | Q30: férias/13 sal
B31: 15 parcela | C31: 1260 | D31: 45597 | G31: viajar mais
B32: 16 parcela | C32: 1260 | D32: 45627 | G32: estar com meus pais
B33: 17 parcela | C33: 1260 | D33: 45658 | G33: Atencao com Sophia na escola | H33: matematica | P33: =((SUM(P27:P28)-SUM(P30:P31))/6) -> 366.66667 | Q33: poupar/mês
B34: 18 parcela | C34: 1260 | D34: 45689 | G34: Atencao com o desenvolvimento da Tina | H34: Ingles
B35: 19 parcela | C35: 1260 | D35: 45717
B36: 20 parcela | C36: 1260 | D36: 45748
B37: 21 parcela | C37: 1400 | D37: 45778
B38: 26600 | C38: 27860
B39: 1260 | C39: recebi a mais ate nov/23

Sheet RESUMO
B2: PLANILHA RESUMO
B4: RESUMO GERAL | C4: Jan | D4: Fev | E4: Mar | F4: Abr | G4: Mai | H4: Jun | I4: Jul | J4: Ago | K4: Set | L4: Out | M4: Nov | N4: Dez | O4: Total
B5: RENDA TOTAL FAMILIAR | C5: ='ORC DOM_2025'!C20 -> 2006.67 | D5: ='ORC DOM_2025'!E20 -> 2712.67 | E5: ='ORC DOM_2025'!G20 -> 2763.27 | F5: ='ORC DOM_2025'!I20 -> 2609.67 | G5: ='ORC DOM_2025'!K20 -> 0 | H5: ='ORC DOM_2025'!M20 -> 0 | I5: ='ORC DOM_2025'!O20 -> 0 | J5: ='ORC DOM_2025'!Q20 -> 1000 | K5: ='ORC DOM_2025'!S20 -> 0 | L5: ='ORC DOM_2025'!U20 -> 0 | M5: ='ORC DOM_2025'!W20 -> 1000 | N5: ='ORC DOM_2025'!Y20 -> 0 | O5: =SUM(C5:N5) -> 12092.28
B6: TOTAL DE DESPESAS | C6: ='ORC DOM_2025'!C113 -> 2028.935 | D6: ='ORC DOM_2025'!E113 -> 2725.435 | E6: ='ORC DOM_2025'!G113 -> 2825.435 | F6: ='ORC DOM_2025'!I113 -> 2720.435 | G6: ='ORC DOM_2025'!K113 -> 2442.81 | H6: ='ORC DOM_2025'!M113 -> 2584.81 | I6: ='ORC DOM_2025'!O113 -> 2404.81 | J6: ='ORC DOM_2025'!Q113 -> 3579.72 | K6: ='ORC DOM_2025'!S113 -> 2229.81 | L6: ='ORC DOM_2025'!U113 -> 2547.31 | M6: ='ORC DOM_2025'!W113 -> 3320.81 | N6: ='ORC DOM_2025'!Y113 -> 2433.81 | O6: =SUM(C6:N6) -> 31844.13
B7: SALDO FINAL | C7: =C5-C6 -> -22.265 | D7: =D5-D6 -> -12.765 | E7: =E5-E6 -> -62.165 | F7: =F5-F6 -> -110.765 | G7: =G5-G6 -> -2442.81 | H7: =H5-H6 -> -2584.81 | I7: =I5-I6 -> -2404.81 | J7: =J5-J6 -> -2579.72 | ... N7: =N5-N6 -> -2433.81 | O7: =SUM(C7:N7) -> -19751.85
B9: RESUMO DAS DESPESAS POR CATEGORIA | C9: Jan | D9: Fev | E9: Mar | F9: Abr | G9: Mai | H9: Jun | I9: Jul | J9: Ago | K9: Set | L9: Out | M9: Nov | N9: Dez | O9: Total por Categoria no ano todo
B10: BOLETO PESSOAL | C10: ='ORC DOM_2025'!C22 -> 0 | D10: ='ORC DOM_2025'!E22 -> 250 | E10: ='ORC DOM_2025'!G22 -> 250 | F10: ='ORC DOM_2025'!I22 -> 250 | G10: ='ORC DOM_2025'!K22 -> 250 | H10: ='ORC DOM_2025'!M22 -> 250 | I10: ='ORC DOM_2025'!O22 -> 250 | J10: ='ORC DOM_2025'!Q22 -> 1250 | K10: ='ORC DOM_2025'!S22 -> 250 | L10: ='ORC DOM_2025'!U22 -> 250 | M10: ='ORC DOM_2025'!W22 -> 1250 | N10: ='ORC DOM_2025'!Y22 -> 250 | O10: =SUM(C10:N10) -> 4750
B11: HABITAÇÃO | C11: ='ORC DOM_2025'!C31 -> 1351.5 | D11: ='ORC DOM_2025'!E31 -> 1511 | E11: ='ORC DOM_2025'!G31 -> 1511 | F11: ='ORC DOM_2025'!I31 -> 1506 | G11: ='ORC DOM_2025'!K31 -> 1506 | H11: ='ORC DOM_2025'!M31 -> 1506 | I11: ='ORC DOM_2025'!O31 -> 1506 | J11: ='ORC DOM_2025'!Q31 -> 1506 | K11: ='ORC DOM_2025'!S31 -> 1506 | L11: ='ORC DOM_2025'!U31 -> 1506 | M11: ='ORC DOM_2025'!W31 -> 1506 | N11: ='ORC DOM_2025'!Y31 -> 1506 | O11: =SUM(C11:N11) -> 17927.5
B12: DÍVIDAS | C12: ='ORC DOM_2025'!C46 -> 165.81 | D12: ='ORC DOM_2025'!E46 -> 165.81 | E12: ='ORC DOM_2025'!G46 -> 165.81 | F12: ='ORC DOM_2025'!I46 -> 165.81 | G12: ='ORC DOM_2025'!K46 -> 165.81 | H12: ='ORC DOM_2025'!M46 -> 165.81 | I12: ='ORC DOM_2025'!O46 -> 165.81 | J12: ='ORC DOM_2025'!Q46 -> 160.72 | K12: ='ORC DOM_2025'!S46 -> 104.81 | L12: ='ORC DOM_2025'!U46 -> 98.31 | M12: ='ORC DOM_2025'!W46 -> 91.81 | N12: ='ORC DOM_2025'!Y46 -> 104.81 | O12: =SUM(C12:N12) -> 1721.13
B13: SAÚDE | C13: ='ORC DOM_2025'!C53 -> 0 | D13: ='ORC DOM_2025'!E53 -> 55 | E13: ='ORC DOM_2025'!G53 -> 55 | F13: ='ORC DOM_2025'!I53 -> 55 | G13: ='ORC DOM_2025'!K53 -> 0 | H13: ='ORC DOM_2025'!M53 -> 0 | I13: ='ORC DOM_2025'!O53 -> 0 | J13: ='ORC DOM_2025'!Q53 -> 0 | K13: ='ORC DOM_2025'!S53 -> 0 | L13: ='ORC DOM_2025'!U53 -> 0 | M13: ='ORC DOM_2025'!W53 -> 0 | N13: ='ORC DOM_2025'!Y53 -> 0 | O13: =SUM(C13:N13) -> 165
B14: TRANSPORTE | C14: ='ORC DOM_2025'!C59 -> 191 | D14: ='ORC DOM_2025'!E59 -> 113 | E14: ='ORC DOM_2025'!G59 -> 113 | F14: ='ORC DOM_2025'!I59 -> 113 | G14: ='ORC DOM_2025'!K59 -> 209 | H14: ='ORC DOM_2025'!M59 -> 203 | I14: ='ORC DOM_2025'!O59 -> 203 | J14: ='ORC DOM_2025'!Q59 -> 203 | K14: ='ORC DOM_2025'!S59 -> 209 | L14: ='ORC DOM_2025'!U59 -> 113 | M14: ='ORC DOM_2025'!W59 -> 313 | N14: ='ORC DOM_2025'!Y59 -> 113 | O14: =SUM(C14:N14) -> 2096
B15: DESPESAS PESSOAIS | C15: ='ORC DOM_2025'!C71 -> 264.465 | D15: ='ORC DOM_2025'!E71 -> 434.465 | E15: ='ORC DOM_2025'!G71 -> 534.465 | F15: ='ORC DOM_2025'!I71 -> 434.465 | G15: ='ORC DOM_2025'!K71 -> 200 | H15: ='ORC DOM_2025'!M71 -> 400 | I15: ='ORC DOM_2025'!O71 -> 220 | J15: ='ORC DOM_2025'!Q71 -> 400 | K15: ='ORC DOM_2025'!S71 -> 100 | L15: ='ORC DOM_2025'!U71 -> 520 | M15: ='ORC DOM_2025'!W71 -> 100 | N15: ='ORC DOM_2025'!Y71 -> 400 | O15: =SUM(C15:N15) -> 4007.86
B16: EDUCAÇÃO | C16: ='ORC DOM_2025'!C83 -> 0 | D16: ='ORC DOM_2025'!E83 -> 60 | E16: ='ORC DOM_2025'!G83 -> 60 | F16: ='ORC DOM_2025'!I83 -> 60 | G16: ='ORC DOM_2025'!K83 -> 60 | H16: ='ORC DOM_2025'!M83 -> 60 | I16: ='ORC DOM_2025'!O83 -> 60 | J16: ='ORC DOM_2025'!Q83 -> 60 | K16: ='ORC DOM_2025'!S83 -> 60 | L16: ='ORC DOM_2025'!U83 -> 60 | M16: ='ORC DOM_2025'!W83 -> 60 | N16: ='ORC DOM_2025'!Y83 -> 60 | O16: =SUM(C16:N16) -> 660
B17: LAZER | C17: ='ORC DOM_2025'!C89 -> 0 | D17: ='ORC DOM_2025'!E89 -> 80 | E17: ='ORC DOM_2025'!G89 -> 80 | F17: ='ORC DOM_2025'!I89 -> 80 | G17: ='ORC DOM_2025'!K89 -> 0 | H17: ='ORC DOM_2025'!M89 -> 0 | I17: ='ORC DOM_2025'!O89 -> 0 | J17: ='ORC DOM_2025'!Q89 -> 0 | K17: ='ORC DOM_2025'!S89 -> 0 | L17: ='ORC DOM_2025'!U89 -> 0 | M17: ='ORC DOM_2025'!W89 -> 0 | N17: ='ORC DOM_2025'!Y89 -> 0 | O17: =SUM(C17:N17) -> 240
B18: OUTROS | C18: ='ORC DOM_2025'!C96 -> 56.16 | D18: ='ORC DOM_2025'!E96 -> 56.16 | E18: ='ORC DOM_2025'!G96 -> 56.16 | F18: ='ORC DOM_2025'!I96 -> 56.16 | G18: ='ORC DOM_2025'!K96 -> 52 | H18: ='ORC DOM_2025'!M96 -> 0 | I18: ='ORC DOM_2025'!O96 -> 0 | J18: ='ORC DOM_2025'!Q96 -> 0 | K18: ='ORC DOM_2025'!S96 -> 0 | L18: ='ORC DOM_2025'!U96 -> 0 | M18: ='ORC DOM_2025'!W96 -> 0 | N18: ='ORC DOM_2025'!Y96 -> 0 | O18: =SUM(C18:N18) -> 276.64
B19: Total no MÊS | C19: =SUM(C10:C18) -> 2028.935 | D19: =SUM(D10:D18) -> 2725.435 | E19: =SUM(E10:E18) -> 2825.435 | F19: =SUM(F10:F18) -> 2720.435 | G19: =SUM(G10:G18) -> 2442.81 | H19: =SUM(H10:H18) -> 2584.81 | I19: =SUM(I10:I18) -> 2404.81 | J19: =SUM(J10:J18) -> 3579.72 | ... O19: =SUM(O10:O18) -> 31844.13
B21: % DE QUANTO A CATEGORIA REPRESENTA COM RELACAO AO SALARIO | C21: Jan | D21: Fev | E21: Mar | F21: Abr | G21: Mai | H21: Jun | I21: Jul | J21: Ago | K21: Set | L21: Out | M21: Nov | N21: Dez | O21: Total
B22: BOLETO PESSOAL | C22: =IFERROR(C10/C$5,0) -> 0 | D22: =IFERROR(D10/D$5,0) -> 0.092160123 | E22: =IFERROR(E10/E$5,0) -> 0.09047252 | F22: =IFERROR(F10/F$5,0) -> 0.095797553 | G22: =IFERROR(G10/G$5,0) -> 0 | H22: =IFERROR(H10/H$5,0) -> 0 | I22: =IFERROR(I10/I$5,0) -> 0 | J22: =IFERROR(J10/J$5,0) -> 1.25 | ... O22: =IFERROR(O10/O$5,0) -> 0.3928126
B23: HABITAÇÃO | C23: =IFERROR(C11/C$5,0) -> 0.67350386 | D23: =IFERROR(D11/D$5,0) -> 0.55701578 | E23: =IFERROR(E11/E$5,0) -> 0.54681591 | F23: =IFERROR(F11/F$5,0) -> 0.57708446 | G23: =IFERROR(G11/G$5,0) -> 0 | H23: =IFERROR(H11/H$5,0) -> 0 | I23: =IFERROR(I11/I$5,0) -> 0 | J23: =IFERROR(J11/J$5,0) -> 1.506 | ... O23: =IFERROR(O11/O$5,0) -> 1.4825575
B24: DÍVIDAS | C24: =IFERROR(C12/C$5,0) -> 0.082629431 | D24: =IFERROR(D12/D$5,0) -> 0.06112428 | E24: =IFERROR(E12/E$5,0) -> 0.060004994 | F24: =IFERROR(F12/F$5,0) -> 0.063536769 | G24: =IFERROR(G12/G$5,0) -> 0 | H24: =IFERROR(H12/H$5,0) -> 0 | I24: =IFERROR(I12/I$5,0) -> 0 | J24: =IFERROR(J12/J$5,0) -> 0.16072 | ... O24: =IFERROR(O12/O$5,0) -> 0.14233296
B25: SAÚDE | C25: =IFERROR(C13/C$5,0) -> 0 | D25: =IFERROR(D13/D$5,0) -> 0.020275227 | E25: =IFERROR(E13/E$5,0) -> 0.019903954 | F25: =IFERROR(F13/F$5,0) -> 0.021075462 | G25: =IFERROR(G13/G$5,0) -> 0 | H25: =IFERROR(H13/H$5,0) -> 0 | I25: =IFERROR(I13/I$5,0) -> 0 | J25: =IFERROR(J13/J$5,0) -> 0 | ... O25: =IFERROR(O13/O$5,0) -> 0.013645069
B26: TRANSPORTE | C26: =IFERROR(C14/C$5,0) -> 0.095182566 | D26: =IFERROR(D14/D$5,0) -> 0.041656375 | E26: =IFERROR(E14/E$5,0) -> 0.040893579 | F26: =IFERROR(F14/F$5,0) -> 0.043300494 | G26: =IFERROR(G14/G$5,0) -> 0 | H26: =IFERROR(H14/H$5,0) -> 0 | I26: =IFERROR(I14/I$5,0) -> 0 | J26: =IFERROR(J14/J$5,0) -> 0.203 | ... O26: =IFERROR(O14/O$5,0) -> 0.17333373
B27: DESPESAS PESSOAIS | C27: =IFERROR(C15/C$5,0) -> 0.13179297 | D27: =IFERROR(D15/D$5,0) -> 0.16016139 | E27: =IFERROR(E15/E$5,0) -> 0.19341758 | F27: =IFERROR(F15/F$5,0) -> 0.16648274 | G27: =IFERROR(G15/G$5,0) -> 0 | H27: =IFERROR(H15/H$5,0) -> 0 | I27: =IFERROR(I15/I$5,0) -> 0 | J27: =IFERROR(J15/J$5,0) -> 0.4 | ... O27: =IFERROR(O15/O$5,0) -> 0.33143956
B28: EDUCAÇÃO | C28: =IFERROR(C16/C$5,0) -> 0 | D28: =IFERROR(D16/D$5,0) -> 0.022118429 | E28: =IFERROR(E16/E$5,0) -> 0.021713405 | F28: =IFERROR(F16/F$5,0) -> 0.022991413 | G28: =IFERROR(G16/G$5,0) -> 0 | H28: =IFERROR(H16/H$5,0) -> 0 | I28: =IFERROR(I16/I$5,0) -> 0 | J28: =IFERROR(J16/J$5,0) -> 0.06 | ... O28: =IFERROR(O16/O$5,0) -> 0.054580278
B29: LAZER | C29: =IFERROR(C17/C$5,0) -> 0 | D29: =IFERROR(D17/D$5,0) -> 0.029491239 | E29: =IFERROR(E17/E$5,0) -> 0.028951206 | F29: =IFERROR(F17/F$5,0) -> 0.030655217 | G29: =IFERROR(G17/G$5,0) -> 0 | H29: =IFERROR(H17/H$5,0) -> 0 | I29: =IFERROR(I17/I$5,0) -> 0 | J29: =IFERROR(J17/J$5,0) -> 0 | ... O29: =IFERROR(O17/O$5,0) -> 0.019847374
B30: OUTROS | C30: =IFERROR(C18/C$5,0) -> 0.027986664 | D30: =IFERROR(D18/D$5,0) -> 0.02070285 | E30: =IFERROR(E18/E$5,0) -> 0.020323747 | F30: =IFERROR(F18/F$5,0) -> 0.021519962 | G30: =IFERROR(G18/G$5,0) -> 0 | H30: =IFERROR(H18/H$5,0) -> 0 | I30: =IFERROR(I18/I$5,0) -> 0 | J30: =IFERROR(J18/J$5,0) -> 0 | ... O30: =IFERROR(O18/O$5,0) -> 0.022877406

Sheet BITCOIN_2025
B2: JANEIRO | C2: FEVEREIRO | D2: MARÇO | E2: ABRIL | F2: MAIO | G2: JUNHO | H2: JULHO | I2: AGOSTO | J2: SETEMBRO | K2: OUTUBRO | L2: NOVEMBRO | M2: DEZEMBRO | P2: TEMPO | Q2: VALOR
A3: Pagamento carro | B3: ='ORC DOM_2025'!C24 | C3: =B3 | D3: =C3 | E3: =D3 | F3: =E3 | G3: =F3 | H3: =G3 | I3: =H3 | J3: =I3 | ... M3: =L3 | O3: 2024 | P3: ANO 1 | Q3: =B12 -> 9853.93 | R3: 1 ano em Portugal | T3: MUDANÇA/ADAPTAÇÃO
A4: Outros | B4: =713/12 -> 59.416667 | C4: =B4 -> 59.416667 | D4: =C4 -> 59.416667 | E4: =D4 -> 59.416667 | F4: =E4 -> 59.416667 | G4: =F4 -> 59.416667 | H4: =G4 -> 59.416667 | I4: =H4 -> 59.416667 | J4: =I4 -> 59.416667 | ... M4: =L4 -> 59.416667 | O4: 2025 | P4: ANO 2 | Q4: =M17 -> 27882.48 | R4: carro pago / visita mae | T4: RECONSTRUÇÃO
A5: Extras | O5: 2026 | P5: ANO 3 | Q5: =Q4+(Q4*N20) -> 69706.199 | R5: viagem Brasil | T5: SOLIDIFICAÇÃO
A6: TOTAL | B6: =SUM(B3:B5) -> 59.416667 | C6: =SUM(C3:C5) -> 59.416667 | D6: =SUM(D3:D5) -> 59.416667 | E6: =SUM(E3:E5) -> 59.416667 | F6: =SUM(F3:F5) -> 59.416667 | G6: =SUM(G3:G5) -> 59.416667 | H6: =SUM(H3:H5) -> 59.416667 | I6: =SUM(I3:I5) -> 59.416667 | ... M6: =SUM(M3:M5) -> 59.416667 | O6: 2027 | P6: ANO 4 | Q6: =Q5+(Q5*N20) -> 174265.5 | T6: REALIZAÇÃO
O7: 2028 | P7: ANO 5 | Q7: =Q6+(Q6*N20) -> 435663.74 | R7: =Q7*0.8% -> 3485.31 | S7: 52 ANOS | T7: APOSENTADORIA
A9: APOSENTADORIA RENDA PASSIVA DE 4000 EUROS AOS 52 ANOS - ATÉ 2028
A11: dolares | B11: 0.1 | C11: 0.1 | D11: 0.1 | E11: 0.1 | F11: 0.1 | G11: 0.1 | H11: 0.1 | I11: 0.1 | J11: 0.1 | K11: 0.1 | L11: 0.1 | M11: 0.1
A12: Acumulado mês | B12: 9853.93 | C12: =B17 -> 10904.681 | D12: =C17 -> 12060.508 | E12: =D17 -> 13331.917 | F12: =E17 -> 14730.467 | G12: =F17 -> 16268.872 | H12: =G17 -> 16337.117 | I12: =H17 -> 18036.188 | J12: =I17 -> 19905.165 | ... M12: =L17 -> 26710.11
A13: Retirada | G13: =(OBJ_2026!S15)+100 -> 1624 | M13: =OBJ_2026!I7+100-800 -> 1564
A14: Aplicaçao mês | B14: =B6 -> 59.416667 | C14: =C6 -> 59.416667 | D14: =D6 -> 59.416667 | E14: =E6 -> 59.416667 | F14: =F6 -> 59.416667 | G14: =G6 -> 59.416667 | H14: =H6 -> 59.416667 | I14: =I6 -> 59.416667 | ... M14: =M6 -> 59.416667
A15: Rendimento | B15: =(B12+B14)*B11 -> 991.33467 | C15: =(C12+C14)*C11 -> 1096.4098 | D15: =(D12+D14)*D11 -> 1211.9924 | E15: =(E12+E14)*E11 -> 1339.1334 | F15: =(F12+F14)*F11 -> 1478.9884 | G15: =(G12+G14)*G11 -> 1632.8289 | H15: =(H12+H14)*H11 -> 1639.6534 | I15: =(I12+I14)*I11 -> 1809.5604 | ... M15: =(M12+M14)*M11 -> 2676.9527
A17: Total mês | B17: =(B12-B13+B14)+B15 -> 10904.681 | C17: =(C12-C13+C14)+C15 -> 12060.508 | D17: =(D12-D13+D14)+D15 -> 13331.917 | E17: =(E12-E13+E14)+E15 -> 14730.467 | F17: =(F12-F13+F14)+F15 -> 16268.872 | G17: =(G12-G13+G14)+G15 -> 16337.117 | H17: =(H12-H13+H14)+H15 -> 18036.188 | I17: =(I12-I13+I14)+I15 -> 19905.165 | ... M17: =(M12-M13+M14)+M15 -> 27882.48
M19: =B17+(B17*N20) -> 27261.703 | N19: MEDIA ANUAL
N20: 1.5

Sheet Carro_25
H4: 2024 | I4: 2025 | J4: 2026
H5: ANO 1 | I5: ANO 2 | J5: ANO 3 | K5: ANO 4 | L5: ANO 5 | M5: ANO 6 | N5: ANO 7 | O5: ANO 8 | P5: ANO 9 | Q5: ANO 10 | T5: TOTAL
F6: TOTAL DA DIVIDA | G6: 13080 | H6: 1308 | I6: 1308 | J6: 1308 | K6: 1308 | L6: 1308 | M6: 1308 | N6: 1308 | O6: 1308 | P6: 1308 | Q6: 1308
H7: 2616 | I7: 2616 | J7: 2616 | K7: 2616 | L7: 2616
F8: ATÉ JUL/27 | H8: 4360 | I8: 4360 | J8: 4360
H9: 0.2522 | I9: 1
H10: jan | I10: fev | J10: mar | K10: abr | L10: mai | M10: jun | N10: jul | O10: ago | P10: set | Q10: out | R10: nov | S10: dez
F11: total ano | G11: 4360 | H11: 363 | I11: 363 | J11: 363 | K11: 363 | L11: 363 | M11: 363 | N11: 363 | O11: 363 | P11: 363 | Q11: 363 | R11: 363 | S11: 363 | T11: =SUM(H11:S11) -> 4356
F12: total mes | H12: 109 | I12: 109 | J12: 109 | K12: 109 | L12: 109 | M12: 109 | N12: 109 | O12: 109 | P12: 109 | Q12: 109 | R12: 109 | S12: 109 | T12: =SUM(H12:S12) -> 1308
F13: total ferias/natal | G13: 4251 | H13: 254 | I13: 254 | J13: 254 | K13: 254 | L13: 254 | M13: 254 | N13: 254 | O13: 254 | P13: 254 | Q13: 254 | R13: 254 | S13: 254 | T13: =SUM(H13:S13) -> 3048
L14: a pagar | M14: =SUM(H11:M11) -> 2178
G15: 6540 | L15: sera pago mensal | M15: =SUM(H12:M12) -> 654
G16: 60 | L16: Bitcoin | M16: =M14-M15 -> 1524
F18: 48.65 | G18: ano 1 | H18: 6 meses | I18: 109 | J18: 3.3 | K18: 29 | L18: dez./24 | M18: 1410.94 | N18: 86 | O18: 115 | P18: 0.2522
H19: 6 meses | I19: 109 | J19: 3.3 | K19: 36 | L19: 45839 | M19: 1459.59 | N19: 50 | P19: 0.5652
F20: 1
G21: ano 2 | H21: 6 meses | I21: 109 | J21: 3.3 | K21: 50 | L21: dez./25 | M21: 2140.74 | N21: - | P21: 1
H22: 6 meses | I22: 109 | J22: 3.3 | K22: - | L22: mai./26 | M22: 0 | P22: 1

Sheet Benefícios
A1: MESES DO ANO | B1: % | C1: 44562 | D1: Meio de Rec./Pag. | E1: % | F1: 44593 | G1: Meio de Rec./Pag. | H1: % | I1: 44621 | J1: Meio de Rec./Pag. | K1: % | L1: 44652 | M1: Meio de Rec./Pag. | N1: % | O1: 44682 | P1: Meio de Rec./Pag. | Q1: % | R1: 44713 | S1: Meio de Rec./Pag. | T1: % | U1: 44743 | V1: Meio de Rec./Pag. | W1: % | X1: 44774 | Y1: Meio de Rec./Pag. | Z1: % | AA1: 44805 | AB1: Meio de Rec./Pag. | AC1: % | AD1: 44835 | AE1: Meio de Rec./Pag. | AF1: % | AG1: 44866 | AH1: Meio de Rec./Pag. | AI1: % | AJ1: 44896 | AK1: Meio de Rec./Pag. | AL1: TOTAL ANO
A2: Benefícios
A3: Vale Refeição | B3: =IFERROR(C3/C$8,0) -> 0 | E3: =IFERROR(F3/F$8,0) -> 0 | H3: =IFERROR(I3/I$8,0) -> 0 | K3: =IFERROR(L3/L$8,0) -> 0 | N3: =IFERROR(O3/O$8,0) -> 0 | Q3: =IFERROR(R3/R$8,0) -> 0 | T3: =IFERROR(U3/U$8,0) -> 0 | W3: =IFERROR(X3/X$8,0) -> 0 | Z3: =IFERROR(AA3/AA$8,0) -> 0 | AC3: =IFERROR(AD3/AD$8,0) -> 0 | AF3: =IFERROR(AG3/AG$8,0) -> 0 | AI3: =IFERROR(AJ3/AJ$8,0) -> 0 | AL3: =C3+F3+I3+L3+O3+R3+U3+X3+AA3+AD3+AG3+AJ3 -> 0
A4: Vale Alimentação | B4: =IFERROR(C4/C$8,0) -> 0 | E4: =IFERROR(F4/F$8,0) -> 0 | H4: =IFERROR(I4/I$8,0) -> 0 | K4: =IFERROR(L4/L$8,0) -> 0 | N4: =IFERROR(O4/O$8,0) -> 0 | Q4: =IFERROR(R4/R$8,0) -> 0 | T4: =IFERROR(U4/U$8,0) -> 0 | W4: =IFERROR(X4/X$8,0) -> 0 | Z4: =IFERROR(AA4/AA$8,0) -> 0 | AC4: =IFERROR(AD4/AD$8,0) -> 0 | AF4: =IFERROR(AG4/AG$8,0) -> 0 | AI4: =IFERROR(AJ4/AJ$8,0) -> 0 | AL4: =C4+F4+I4+L4+O4+R4+U4+X4+AA4+AD4+AG4+AJ4 -> 0
A5: Vale Transporte | B5: =IFERROR(C5/C$8,0) -> 0 | E5: =IFERROR(F5/F$8,0) -> 0 | H5: =IFERROR(I5/I$8,0) -> 0 | K5: =IFERROR(L5/L$8,0) -> 0 | N5: =IFERROR(O5/O$8,0) -> 0 | Q5: =IFERROR(R5/R$8,0) -> 0 | T5: =IFERROR(U5/U$8,0) -> 0 | W5: =IFERROR(X5/X$8,0) -> 0 | Z5: =IFERROR(AA5/AA$8,0) -> 0 | AC5: =IFERROR(AD5/AD$8,0) -> 0 | AF5: =IFERROR(AG5/AG$8,0) -> 0 | AI5: =IFERROR(AJ5/AJ$8,0) -> 0 | AL5: =C5+F5+I5+L5+O5+R5+U5+X5+AA5+AD5+AG5+AJ5 -> 0
A6: Outros | B6: =IFERROR(C6/C$8,0) -> 0 | E6: =IFERROR(F6/F$8,0) -> 0 | H6: =IFERROR(I6/I$8,0) -> 0 | K6: =IFERROR(L6/L$8,0) -> 0 | N6: =IFERROR(O6/O$8,0) -> 0 | Q6: =IFERROR(R6/R$8,0) -> 0 | T6: =IFERROR(U6/U$8,0) -> 0 | W6: =IFERROR(X6/X$8,0) -> 0 | Z6: =IFERROR(AA6/AA$8,0) -> 0 | AC6: =IFERROR(AD6/AD$8,0) -> 0 | AF6: =IFERROR(AG6/AG$8,0) -> 0 | AI6: =IFERROR(AJ6/AJ$8,0) -> 0 | AL6: =C6+F6+I6+L6+O6+R6+U6+X6+AA6+AD6+AG6+AJ6 -> 0
B7: =IFERROR(C7/C$8,0) -> 0 | E7: =IFERROR(F7/F$8,0) -> 0 | H7: =IFERROR(I7/I$8,0) -> 0 | K7: =IFERROR(L7/L$8,0) -> 0 | N7: =IFERROR(O7/O$8,0) -> 0 | Q7: =IFERROR(R7/R$8,0) -> 0 | T7: =IFERROR(U7/U$8,0) -> 0 | W7: =IFERROR(X7/X$8,0) -> 0 | Z7: =IFERROR(AA7/AA$8,0) -> 0 | AC7: =IFERROR(AD7/AD$8,0) -> 0 | AF7: =IFERROR(AG7/AG$8,0) -> 0 | AI7: =IFERROR(AJ7/AJ$8,0) -> 0 | AL7: =C7+F7+I7+L7+O7+R7+U7+X7+AA7+AD7+AG7+AJ7 -> 0
A8: Total Benefícios | B8: 1 | C8: =SUM(C3:C7) -> 0 | E8: 1 | F8: =SUM(F3:F7) -> 0 | H8: 1 | I8: =SUM(I3:I7) -> 0 | K8: 1 | L8: =SUM(L3:L7) -> 0 | N8: 1 | O8: =SUM(O3:O7) -> 0 | Q8: 1 | R8: =SUM(R3:R7) -> 0 | T8: 1 | U8: =SUM(U3:U7) -> 0 | W8: 1 | X8: =SUM(X3:X7) -> 0 | Z8: 1 | AA8: =SUM(AA3:AA7) -> 0 | AC8: 1 | AD8: =SUM(AD3:AD7) -> 0 | AF8: 1 | AG8: =SUM(AG3:AG7) -> 0 | AI8: 1 | AJ8: =SUM(AJ3:AJ7) -> 0 | AL8: =SUM(AL3:AL7) -> 0
A10: Alimentação/Refeição | B10: =IFERROR(C10/C$8,0) -> 0 | C10: =SUM(C11:C17) -> 0 | E10: =IFERROR(F10/F$8,0) -> 0 | F10: =SUM(F11:F17) -> 0 | H10: =IFERROR(I10/I$8,0) -> 0 | I10: =SUM(I11:I17) -> 0 | K10: =IFERROR(L10/L$8,0) -> 0 | L10: =SUM(L11:L17) -> 0 | N10: =IFERROR(O10/O$8,0) -> 0 | O10: =SUM(O11:O17) -> 0 | Q10: =IFERROR(R10/R$8,0) -> 0 | R10: =SUM(R11:R17) -> 0 | T10: =IFERROR(U10/U$8,0) -> 0 | U10: =SUM(U11:U17) -> 0 | W10: =IFERROR(X10/X$8,0) -> 0 | X10: =SUM(X11:X17) -> 0 | Z10: =IFERROR(AA10/AA$8,0) -> 0 | AA10: =SUM(AA11:AA17) -> 0 | AC10: =IFERROR(AD10/AD$8,0) -> 0 | AD10: =SUM(AD11:AD17) -> 0 | AF10: =IFERROR(AG10/AG$8,0) -> 0 | AG10: =SUM(AG11:AG17) -> 0 | AI10: =IFERROR(AJ10/AJ$8,0) -> 0 | AJ10: =SUM(AJ11:AJ17) -> 0 | AL10: =C10+F10+I10+L10+O10+R10+U10+X10+AA10+AD10+AG10+AJ10 -> 0
A11: Supermercado | B11: =IFERROR(C11/C$8,0) -> 0 | E11: =IFERROR(F11/F$8,0) -> 0 | H11: =IFERROR(I11/I$8,0) -> 0 | K11: =IFERROR(L11/L$8,0) -> 0 | N11: =IFERROR(O11/O$8,0) -> 0 | Q11: =IFERROR(R11/R$8,0) -> 0 | T11: =IFERROR(U11/U$8,0) -> 0 | W11: =IFERROR(X11/X$8,0) -> 0 | Z11: =IFERROR(AA11/AA$8,0) -> 0 | AC11: =IFERROR(AD11/AD$8,0) -> 0 | AF11: =IFERROR(AG11/AG$8,0) -> 0 | AI11: =IFERROR(AJ11/AJ$8,0) -> 0 | AL11: =C11+F11+I11+L11+O11+R11+U11+X11+AA11+AD11+AG11+AJ11 -> 0
A12: Restaurante | B12: =IFERROR(C12/C$8,0) -> 0 | E12: =IFERROR(F12/F$8,0) -> 0 | H12: =IFERROR(I12/I$8,0) -> 0 | K12: =IFERROR(L12/L$8,0) -> 0 | N12: =IFERROR(O12/O$8,0) -> 0 | Q12: =IFERROR(R12/R$8,0) -> 0 | T12: =IFERROR(U12/U$8,0) -> 0 | W12: =IFERROR(X12/X$8,0) -> 0 | Z12: =IFERROR(AA12/AA$8,0) -> 0 | AC12: =IFERROR(AD12/AD$8,0) -> 0 | AF12: =IFERROR(AG12/AG$8,0) -> 0 | AI12: =IFERROR(AJ12/AJ$8,0) -> 0 | AL12: =C12+F12+I12+L12+O12+R12+U12+X12+AA12+AD12+AG12+AJ12 -> 0
A13: Bar | B13: =IFERROR(C13/C$8,0) -> 0 | E13: =IFERROR(F13/F$8,0) -> 0 | H13: =IFERROR(I13/I$8,0) -> 0 | K13: =IFERROR(L13/L$8,0) -> 0 | N13: =IFERROR(O13/O$8,0) -> 0 | Q13: =IFERROR(R13/R$8,0) -> 0 | T13: =IFERROR(U13/U$8,0) -> 0 | W13: =IFERROR(X13/X$8,0) -> 0 | Z13: =IFERROR(AA13/AA$8,0) -> 0 | AC13: =IFERROR(AD13/AD$8,0) -> 0 | AF13: =IFERROR(AG13/AG$8,0) -> 0 | AI13: =IFERROR(AJ13/AJ$8,0) -> 0 | AL13: =C13+F13+I13+L13+O13+R13+U13+X13+AA13+AD13+AG13+AJ13 -> 0
A14: Ifood | B14: =IFERROR(C14/C$8,0) -> 0 | E14: =IFERROR(F14/F$8,0) -> 0 | H14: =IFERROR(I14/I$8,0) -> 0 | K14: =IFERROR(L14/L$8,0) -> 0 | N14: =IFERROR(O14/O$8,0) -> 0 | Q14: =IFERROR(R14/R$8,0) -> 0 | T14: =IFERROR(U14/U$8,0) -> 0 | W14: =IFERROR(X14/X$8,0) -> 0 | Z14: =IFERROR(AA14/AA$8,0) -> 0 | AC14: =IFERROR(AD14/AD$8,0) -> 0 | AF14: =IFERROR(AG14/AG$8,0) -> 0 | AI14: =IFERROR(AJ14/AJ$8,0) -> 0 | AL14: =C14+F14+I14+L14+O14+R14+U14+X14+AA14+AD14+AG14+AJ14 -> 0
A15: Outros | B15: =IFERROR(C15/C$8,0) -> 0 | E15: =IFERROR(F15/F$8,0) -> 0 | H15: =IFERROR(I15/I$8,0) -> 0 | K15: =IFERROR(L15/L$8,0) -> 0 | N15: =IFERROR(O15/O$8,0) -> 0 | Q15: =IFERROR(R15/R$8,0) -> 0 | T15: =IFERROR(U15/U$8,0) -> 0 | W15: =IFERROR(X15/X$8,0) -> 0 | Z15: =IFERROR(AA15/AA$8,0) -> 0 | AC15: =IFERROR(AD15/AD$8,0) -> 0 | AF15: =IFERROR(AG15/AG$8,0) -> 0 | AI15: =IFERROR(AJ15/AJ$8,0) -> 0 | AL15: =C15+F15+I15+L15+O15+R15+U15+X15+AA15+AD15+AG15+AJ15 -> 0
B16: =IFERROR(C16/C$8,0) -> 0 | E16: =IFERROR(F16/F$8,0) -> 0 | H16: =IFERROR(I16/I$8,0) -> 0 | K16: =IFERROR(L16/L$8,0) -> 0 | N16: =IFERROR(O16/O$8,0) -> 0 | Q16: =IFERROR(R16/R$8,0) -> 0 | T16: =IFERROR(U16/U$8,0) -> 0 | W16: =IFERROR(X16/X$8,0) -> 0 | Z16: =IFERROR(AA16/AA$8,0) -> 0 | AC16: =IFERROR(AD16/AD$8,0) -> 0 | AF16: =IFERROR(AG16/AG$8,0) -> 0 | AI16: =IFERROR(AJ16/AJ$8,0) -> 0
B17: =IFERROR(C17/C$8,0) -> 0 | E17: =IFERROR(F17/F$8,0) -> 0 | H17: =IFERROR(I17/I$8,0) -> 0 | K17: =IFERROR(L17/L$8,0) -> 0 | N17: =IFERROR(O17/O$8,0) -> 0 | Q17: =IFERROR(R17/R$8,0) -> 0 | T17: =IFERROR(U17/U$8,0) -> 0 | W17: =IFERROR(X17/X$8,0) -> 0 | Z17: =IFERROR(AA17/AA$8,0) -> 0 | AC17: =IFERROR(AD17/AD$8,0) -> 0 | AF17: =IFERROR(AG17/AG$8,0) -> 0 | AI17: =IFERROR(AJ17/AJ$8,0) -> 0 | AL17: =C17+F17+I17+L17+O17+R17+U17+X17+AA17+AD17+AG17+AJ17 -> 0
A18: Transporte | B18: =IFERROR(C18/C$8,0) -> 0 | C18: =SUM(C19:C27) -> 0 | E18: =IFERROR(F18/F$8,0) -> 0 | F18: =SUM(F19:F27) -> 0 | H18: =IFERROR(I18/I$8,0) -> 0 | I18: =SUM(I19:I27) -> 0 | K18: =IFERROR(L18/L$8,0) -> 0 | L18: =SUM(L19:L27) -> 0 | N18: =IFERROR(O18/O$8,0) -> 0 | O18: =SUM(O19:O27) -> 0 | Q18: =IFERROR(R18/R$8,0) -> 0 | R18: =SUM(R19:R27) -> 0 | T18: =IFERROR(U18/U$8,0) -> 0 | U18: =SUM(U19:U27) -> 0 | W18: =IFERROR(X18/X$8,0) -> 0 | X18: =SUM(X19:X27) -> 0 | Z18: =IFERROR(AA18/AA$8,0) -> 0 | AA18: =SUM(AA19:AA27) -> 0 | AC18: =IFERROR(AD18/AD$8,0) -> 0 | AD18: =SUM(AD19:AD27) -> 0 | AF18: =IFERROR(AG18/AG$8,0) -> 0 | AG18: =SUM(AG19:AG27) -> 0 | AI18: =IFERROR(AJ18/AJ$8,0) -> 0 | AJ18: =SUM(AJ19:AJ27) -> 0 | AL18: =C18+F18+I18+L18+O18+R18+U18+X18+AA18+AD18+AG18+AJ18 -> 0
A19: Ônibus | B19: =IFERROR(C19/C$8,0) -> 0 | E19: =IFERROR(F19/F$8,0) -> 0 | H19: =IFERROR(I19/I$8,0) -> 0 | K19: =IFERROR(L19/L$8,0) -> 0 | N19: =IFERROR(O19/O$8,0) -> 0 | Q19: =IFERROR(R19/R$8,0) -> 0 | T19: =IFERROR(U19/U$8,0) -> 0 | W19: =IFERROR(X19/X$8,0) -> 0 | Z19: =IFERROR(AA19/AA$8,0) -> 0 | AC19: =IFERROR(AD19/AD$8,0) -> 0 | AF19: =IFERROR(AG19/AG$8,0) -> 0 | AI19: =IFERROR(AJ19/AJ$8,0) -> 0 | AL19: =C19+F19+I19+L19+O19+R19+U19+X19+AA19+AD19+AG19+AJ19 -> 0
A20: Metrô | B20: =IFERROR(C20/C$8,0) -> 0 | E20: =IFERROR(F20/F$8,0) -> 0 | H20: =IFERROR(I20/I$8,0) -> 0 | K20: =IFERROR(L20/L$8,0) -> 0 | N20: =IFERROR(O20/O$8,0) -> 0 | Q20: =IFERROR(R20/R$8,0) -> 0 | T20: =IFERROR(U20/U$8,0) -> 0 | W20: =IFERROR(X20/X$8,0) -> 0 | Z20: =IFERROR(AA20/AA$8,0) -> 0 | AC20: =IFERROR(AD20/AD$8,0) -> 0 | AF20: =IFERROR(AG20/AG$8,0) -> 0 | AI20: =IFERROR(AJ20/AJ$8,0) -> 0 | AL20: =C20+F20+I20+L20+O20+R20+U20+X20+AA20+AD20+AG20+AJ20 -> 0
A21: Uber | B21: =IFERROR(C21/C$8,0) -> 0 | E21: =IFERROR(F21/F$8,0) -> 0 | H21: =IFERROR(I21/I$8,0) -> 0 | K21: =IFERROR(L21/L$8,0) -> 0 | N21: =IFERROR(O21/O$8,0) -> 0 | Q21: =IFERROR(R21/R$8,0) -> 0 | T21: =IFERROR(U21/U$8,0) -> 0 | W21: =IFERROR(X21/X$8,0) -> 0 | Z21: =IFERROR(AA21/AA$8,0) -> 0 | AC21: =IFERROR(AD21/AD$8,0) -> 0 | AF21: =IFERROR(AG21/AG$8,0) -> 0 | AI21: =IFERROR(AJ21/AJ$8,0) -> 0 | AL21: =C21+F21+I21+L21+O21+R21+U21+X21+AA21+AD21+AG21+AJ21 -> 0
A22: 99 | B22: =IFERROR(C22/C$8,0) -> 0 | E22: =IFERROR(F22/F$8,0) -> 0 | H22: =IFERROR(I22/I$8,0) -> 0 | K22: =IFERROR(L22/L$8,0) -> 0 | N22: =IFERROR(O22/O$8,0) -> 0 | Q22: =IFERROR(R22/R$8,0) -> 0 | T22: =IFERROR(U22/U$8,0) -> 0 | W22: =IFERROR(X22/X$8,0) -> 0 | Z22: =IFERROR(AA22/AA$8,0) -> 0 | AC22: =IFERROR(AD22/AD$8,0) -> 0 | AF22: =IFERROR(AG22/AG$8,0) -> 0 | AI22: =IFERROR(AJ22/AJ$8,0) -> 0 | AL22: =C22+F22+I22+L22+O22+R22+U22+X22+AA22+AD22+AG22+AJ22 -> 0
A23: Táxi | B23: =IFERROR(C23/C$8,0) -> 0 | E23: =IFERROR(F23/F$8,0) -> 0 | H23: =IFERROR(I23/I$8,0) -> 0 | K23: =IFERROR(L23/L$8,0) -> 0 | N23: =IFERROR(O23/O$8,0) -> 0 | Q23: =IFERROR(R23/R$8,0) -> 0 | T23: =IFERROR(U23/U$8,0) -> 0 | W23: =IFERROR(X23/X$8,0) -> 0 | Z23: =IFERROR(AA23/AA$8,0) -> 0 | AC23: =IFERROR(AD23/AD$8,0) -> 0 | AF23: =IFERROR(AG23/AG$8,0) -> 0 | AI23: =IFERROR(AJ23/AJ$8,0) -> 0 | AL23: =C23+F23+I23+L23+O23+R23+U23+X23+AA23+AD23+AG23+AJ23 -> 0
A24: Combustível | B24: =IFERROR(C24/C$8,0) -> 0 | E24: =IFERROR(F24/F$8,0) -> 0 | H24: =IFERROR(I24/I$8,0) -> 0 | K24: =IFERROR(L24/L$8,0) -> 0 | N24: =IFERROR(O24/O$8,0) -> 0 | Q24: =IFERROR(R24/R$8,0) -> 0 | T24: =IFERROR(U24/U$8,0) -> 0 | W24: =IFERROR(X24/X$8,0) -> 0 | Z24: =IFERROR(AA24/AA$8,0) -> 0 | AC24: =IFERROR(AD24/AD$8,0) -> 0 | AF24: =IFERROR(AG24/AG$8,0) -> 0 | AI24: =IFERROR(AJ24/AJ$8,0) -> 0 | AL24: =C24+F24+I24+L24+O24+R24+U24+X24+AA24+AD24+AG24+AJ24 -> 0
A25: Outros | B25: =IFERROR(C25/C$8,0) -> 0 | E25: =IFERROR(F25/F$8,0) -> 0 | H25: =IFERROR(I25/I$8,0) -> 0 | K25: =IFERROR(L25/L$8,0) -> 0 | N25: =IFERROR(O25/O$8,0) -> 0 | Q25: =IFERROR(R25/R$8,0) -> 0 | T25: =IFERROR(U25/U$8,0) -> 0 | W25: =IFERROR(X25/X$8,0) -> 0 | Z25: =IFERROR(AA25/AA$8,0) -> 0 | AC25: =IFERROR(AD25/AD$8,0) -> 0 | AF25: =IFERROR(AG25/AG$8,0) -> 0 | AI25: =IFERROR(AJ25/AJ$8,0) -> 0 | AL25: =C25+F25+I25+L25+O25+R25+U25+X25+AA25+AD25+AG25+AJ25 -> 0
B26: =IFERROR(C26/C$8,0) -> 0 | E26: =IFERROR(F26/F$8,0) -> 0 | H26: =IFERROR(I26/I$8,0) -> 0 | K26: =IFERROR(L26/L$8,0) -> 0 | N26: =IFERROR(O26/O$8,0) -> 0 | Q26: =IFERROR(R26/R$8,0) -> 0 | T26: =IFERROR(U26/U$8,0) -> 0 | W26: =IFERROR(X26/X$8,0) -> 0 | Z26: =IFERROR(AA26/AA$8,0) -> 0 | AC26: =IFERROR(AD26/AD$8,0) -> 0 | AF26: =IFERROR(AG26/AG$8,0) -> 0 | AI26: =IFERROR(AJ26/AJ$8,0) -> 0 | AL26: =C26+F26+I26+L26+O26+R26+U26+X26+AA26+AD26+AG26+AJ26 -> 0
B27: =IFERROR(C27/C$8,0) -> 0 | E27: =IFERROR(F27/F$8,0) -> 0 | H27: =IFERROR(I27/I$8,0) -> 0 | K27: =IFERROR(L27/L$8,0) -> 0 | N27: =IFERROR(O27/O$8,0) -> 0 | Q27: =IFERROR(R27/R$8,0) -> 0 | T27: =IFERROR(U27/U$8,0) -> 0 | W27: =IFERROR(X27/X$8,0) -> 0 | Z27: =IFERROR(AA27/AA$8,0) -> 0 | AC27: =IFERROR(AD27/AD$8,0) -> 0 | AF27: =IFERROR(AG27/AG$8,0) -> 0 | AI27: =IFERROR(AJ27/AJ$8,0) -> 0 | AL27: =C27+F27+I27+L27+O27+R27+U27+X27+AA27+AD27+AG27+AJ27 -> 0
A28: Total Gastos Benefícios | B28: =IFERROR(C28/C$8,0) -> 0 | C28: =C10+C18 -> 0 | E28: =IFERROR(F28/F$8,0) -> 0 | F28: =F10+F18 -> 0 | H28: =IFERROR(I28/I$8,0) -> 0 | I28: =I10+I18 -> 0 | K28: =IFERROR(L28/L$8,0) -> 0 | L28: =L10+L18 -> 0 | N28: =IFERROR(O28/O$8,0) -> 0 | O28: =O10+O18 -> 0 | Q28: =IFERROR(R28/R$8,0) -> 0 | R28: =R10+R18 -> 0 | T28: =IFERROR(U28/U$8,0) -> 0 | U28: =U10+U18 -> 0 | W28: =IFERROR(X28/X$8,0) -> 0 | X28: =X10+X18 -> 0 | Z28: =IFERROR(AA28/AA$8,0) -> 0 | AA28: =AA10+AA18 -> 0 | AC28: =IFERROR(AD28/AD$8,0) -> 0 | AD28: =AD10+AD18 -> 0 | AF28: =IFERROR(AG28/AG$8,0) -> 0 | AG28: =AG10+AG18 -> 0 | AI28: =IFERROR(AJ28/AJ$8,0) -> 0 | AJ28: =AJ10+AJ18 -> 0 | AL28: =C28+F28+I28+L28+O28+R28+U28+X28+AA28+AD28+AG28+AJ28 -> 0
A30: Saldo Disponível no mês | B30: =C8-C28 -> 0 | E30: =F8-F28 -> 0 | H30: =I8-I28 -> 0 | K30: =L8-L28 -> 0 | N30: =O8-O28 -> 0 | Q30: =R8-R28 -> 0 | T30: =U8-U28 -> 0 | W30: =X8-X28 -> 0 | Z30: =AA8-AA28 -> 0 | AC30: =AD8-AD28 -> 0 | AF30: =AG8-AG28 -> 0 | AI30: =AJ8-AJ28 -> 0 | AL30: =SUM(B30:AJ30) -> 0

Sheet Como Gasto

Sheet Rec x Desp

Sheet Boleto Pessoal

Sheet Habitação

Sheet Dívidas

Sheet Saúde

Sheet Transporte

Sheet Desp Pessoais

Sheet Educação

Sheet Lazer

Sheet Outros

Sheet Dados
B4: PLANILHA SUPORTE PARA OS GRAFICOS
C7: Jan | D7: Fev | E7: Mar | F7: Abr | G7: Mai | H7: Jun | I7: Jul | J7: Ago | K7: Set | L7: Out | M7: Nov | N7: Dez | O7: Total
B8: BOLETO PESSOAL | C8: ='ORC DOM_2025'!C22 -> 0 | D8: ='ORC DOM_2025'!E22 -> 250 | E8: ='ORC DOM_2025'!G22 -> 250 | F8: ='ORC DOM_2025'!I22 -> 250 | G8: ='ORC DOM_2025'!K22 -> 250 | H8: ='ORC DOM_2025'!M22 -> 250 | I8: ='ORC DOM_2025'!O22 -> 250 | J8: ='ORC DOM_2025'!Q22 -> 1250 | K8: ='ORC DOM_2025'!S22 -> 250 | L8: ='ORC DOM_2025'!U22 -> 250 | M8: ='ORC DOM_2025'!W22 -> 1250 | N8: ='ORC DOM_2025'!Y22 -> 250 | O8: =SUM(C8:N8) -> 4750
B9: ='ORC DOM_2025'!A31 -> HABITAÇÃO | C9: ='ORC DOM_2025'!C31 -> 1351.5 | D9: ='ORC DOM_2025'!E31 -> 1511 | E9: ='ORC DOM_2025'!G31 -> 1511 | F9: ='ORC DOM_2025'!I31 -> 1506 | G9: ='ORC DOM_2025'!K31 -> 1506 | H9: ='ORC DOM_2025'!M31 -> 1506 | I9: ='ORC DOM_2025'!O31 -> 1506 | J9: ='ORC DOM_2025'!Q31 -> 1506 | K9: ='ORC DOM_2025'!S31 -> 1506 | L9: ='ORC DOM_2025'!U31 -> 1506 | M9: ='ORC DOM_2025'!W31 -> 1506 | N9: ='ORC DOM_2025'!Y31 -> 1506 | O9: =SUM(C9:N9) -> 17927.5
B10: DÍVIDAS | C10: ='ORC DOM_2025'!C46 -> 165.81 | D10: ='ORC DOM_2025'!E46 -> 165.81 | E10: ='ORC DOM_2025'!G46 -> 165.81 | F10: ='ORC DOM_2025'!I46 -> 165.81 | G10: ='ORC DOM_2025'!K46 -> 165.81 | H10: ='ORC DOM_2025'!M46 -> 165.81 | I10: ='ORC DOM_2025'!O46 -> 165.81 | J10: ='ORC DOM_2025'!Q46 -> 160.72 | K10: ='ORC DOM_2025'!S46 -> 104.81 | L10: ='ORC DOM_2025'!U46 -> 98.31 | M10: ='ORC DOM_2025'!W46 -> 91.81 | N10: ='ORC DOM_2025'!Y46 -> 104.81 | O10: =SUM(C10:N10) -> 1721.13
B11: ='ORC DOM_2025'!A53 -> SAÚDE | C11: ='ORC DOM_2025'!C53 -> 0 | D11: ='ORC DOM_2025'!E53 -> 55 | E11: ='ORC DOM_2025'!G53 -> 55 | F11: ='ORC DOM_2025'!I53 -> 55 | G11: ='ORC DOM_2025'!K53 -> 0 | H11: ='ORC DOM_2025'!M53 -> 0 | I11: ='ORC DOM_2025'!O53 -> 0 | J11: ='ORC DOM_2025'!Q53 -> 0 | K11: ='ORC DOM_2025'!S53 -> 0 | L11: ='ORC DOM_2025'!U53 -> 0 | M11: ='ORC DOM_2025'!W53 -> 0 | N11: ='ORC DOM_2025'!Y53 -> 0 | O11: =SUM(C11:N11) -> 165
B12: ='ORC DOM_2025'!A59 -> TRANSPORTE | C12: ='ORC DOM_2025'!C59 -> 191 | D12: ='ORC DOM_2025'!E59 -> 113 | E12: ='ORC DOM_2025'!G59 -> 113 | F12: ='ORC DOM_2025'!I59 -> 113 | G12: ='ORC DOM_2025'!K59 -> 209 | H12: ='ORC DOM_2025'!M59 -> 203 | I12: ='ORC DOM_2025'!O59 -> 203 | J12: ='ORC DOM_2025'!Q59 -> 203 | K12: ='ORC DOM_2025'!S59 -> 209 | L12: ='ORC DOM_2025'!U59 -> 113 | M12: ='ORC DOM_2025'!W59 -> 313 | N12: ='ORC DOM_2025'!Y59 -> 113 | O12: =SUM(C12:N12) -> 2096
B13: ='ORC DOM_2025'!A71 -> DESPESAS PESSOAIS | C13: ='ORC DOM_2025'!C71 -> 264.465 | D13: ='ORC DOM_2025'!E71 -> 434.465 | E13: ='ORC DOM_2025'!G71 -> 534.465 | F13: ='ORC DOM_2025'!I71 -> 434.465 | G13: ='ORC DOM_2025'!K71 -> 200 | H13: ='ORC DOM_2025'!M71 -> 400 | I13: ='ORC DOM_2025'!O71 -> 220 | J13: ='ORC DOM_2025'!Q71 -> 400 | K13: ='ORC DOM_2025'!S71 -> 100 | L13: ='ORC DOM_2025'!U71 -> 520 | M13: ='ORC DOM_2025'!W71 -> 100 | N13: ='ORC DOM_2025'!Y71 -> 400 | O13: =SUM(C13:N13) -> 4007.86
B14: ='ORC DOM_2025'!A83 -> EDUCAÇÃO | C14: ='ORC DOM_2025'!C83 -> 0 | D14: ='ORC DOM_2025'!E83 -> 60 | E14: ='ORC DOM_2025'!G83 -> 60 | F14: ='ORC DOM_2025'!I83 -> 60 | G14: ='ORC DOM_2025'!K83 -> 60 | H14: ='ORC DOM_2025'!M83 -> 60 | I14: ='ORC DOM_2025'!O83 -> 60 | J14: ='ORC DOM_2025'!Q83 -> 60 | K14: ='ORC DOM_2025'!S83 -> 60 | L14: ='ORC DOM_2025'!U83 -> 60 | M14: ='ORC DOM_2025'!W83 -> 60 | N14: ='ORC DOM_2025'!Y83 -> 60 | O14: =SUM(C14:N14) -> 660
B15: ='ORC DOM_2025'!A89 -> LAZER | C15: ='ORC DOM_2025'!C89 -> 0 | D15: ='ORC DOM_2025'!E89 -> 80 | E15: ='ORC DOM_2025'!G89 -> 80 | F15: ='ORC DOM_2025'!I89 -> 80 | G15: ='ORC DOM_2025'!K89 -> 0 | H15: ='ORC DOM_2025'!M89 -> 0 | I15: ='ORC DOM_2025'!O89 -> 0 | J15: ='ORC DOM_2025'!Q89 -> 0 | K15: ='ORC DOM_2025'!S89 -> 0 | L15: ='ORC DOM_2025'!U89 -> 0 | M15: ='ORC DOM_2025'!W89 -> 0 | N15: ='ORC DOM_2025'!Y89 -> 0 | O15: =SUM(C15:N15) -> 240
B16: ='ORC DOM_2025'!A96 -> OUTROS | C16: ='ORC DOM_2025'!C96 -> 56.16 | D16: ='ORC DOM_2025'!E96 -> 56.16 | E16: ='ORC DOM_2025'!G96 -> 56.16 | F16: ='ORC DOM_2025'!I96 -> 56.16 | G16: ='ORC DOM_2025'!K96 -> 52 | H16: ='ORC DOM_2025'!M96 -> 0 | I16: ='ORC DOM_2025'!O96 -> 0 | J16: ='ORC DOM_2025'!Q96 -> 0 | K16: ='ORC DOM_2025'!S96 -> 0 | L16: ='ORC DOM_2025'!U96 -> 0 | M16: ='ORC DOM_2025'!W96 -> 0 | N16: ='ORC DOM_2025'!Y96 -> 0 | O16: =SUM(C16:N16) -> 276.64
C20: 1o Trim | D20: 2o Trim | E20: 3o Trim | F20: 4o Trim | G20: TOTAL
B21: BOLETO PESSOAL | C21: =SUM(C8:E8) -> 500 | D21: =SUM(F8:H8) -> 750 | E21: =SUM(I8:K8) -> 1750 | F21: =SUM(L8:N8) -> 1750 | G21: =SUM(C21:F21) -> 4750
B22: HABITAÇÃO | C22: =SUM(C9:E9) -> 4373.5 | D22: =SUM(F9:H9) -> 4518 | E22: =SUM(I9:K9) -> 4518 | F22: =SUM(L9:N9) -> 4518 | G22: =SUM(C22:F22) -> 17927.5
B23: DÍVIDAS | C23: =SUM(C10:E10) -> 497.43 | D23: =SUM(F10:H10) -> 497.43 | E23: =SUM(I10:K10) -> 431.34 | F23: =SUM(L10:N10) -> 294.93 | G23: =SUM(C23:F23) -> 1721.13
B24: SAÚDE | C24: =SUM(C11:E11) -> 110 | D24: =SUM(F11:H11) -> 55 | E24: =SUM(I11:K11) -> 0 | F24: =SUM(L11:N11) -> 0 | G24: =SUM(C24:F24) -> 165
B25: TRANSPORTE | C25: =SUM(C12:E12) -> 417 | D25: =SUM(F12:H12) -> 525 | E25: =SUM(I12:K12) -> 615 | F25: =SUM(L12:N12) -> 539 | G25: =SUM(C25:F25) -> 2096
B26: DESPESAS PESSOAIS | C26: =SUM(C13:E13) -> 1233.395 | D26: =SUM(F13:H13) -> 1034.465 | E26: =SUM(I13:K13) -> 720 | F26: =SUM(L13:N13) -> 1020 | G26: =SUM(C26:F26) -> 4007.86
B27: EDUCAÇÃO | C27: =SUM(C14:E14) -> 120 | D27: =SUM(F14:H14) -> 180 | E27: =SUM(I14:K14) -> 180 | F27: =SUM(L14:N14) -> 180 | G27: =SUM(C27:F27) -> 660
B28: LAZER | C28: =SUM(C15:E15) -> 160 | D28: =SUM(F15:H15) -> 80 | E28: =SUM(I15:K15) -> 0 | F28: =SUM(L15:N15) -> 0 | G28: =SUM(C28:F28) -> 240
B29: OUTROS | C29: =SUM(C16:E16) -> 168.48 | D29: =SUM(F16:H16) -> 108.16 | E29: =SUM(I16:K16) -> 0 | F29: =SUM(L16:N16) -> 0 | G29: =SUM(C29:F29) -> 276.64
B30: TOTAL | C30: =SUM(C21:C29) -> 7579.805 | D30: =SUM(D21:D29) -> 7748.055 | E30: =SUM(E21:E29) -> 8214.34 | F30: =SUM(F21:F29) -> 8301.93 | G30: =SUM(G21:G29) -> 31844.13
C33: 1o Trim | D33: 2o Trim | E33: 3o Trim | F33: 4o Trim | G33: TOTAL
